Workbook

Sheet INSTRUCTIONS
A1: TEMPLATE_30d_matrix -- CRYSTAL CLEAR INSTRUCTIONS (2026-09-11) -- ANY DUMB AGENT CAN EXECUTE *** ON S1 NEVER ON MACBOOK *** If you are reading this, YOU MUST FOLLOW EVERY LINE. No skipping, no guessing, no inventing numbers. This tab + FILTER_DICTIONARY_V2 + v14_sequential_filler.py + v12_quick_engine/backtest_v12_engine are LAW.
A2: ⚠️ MACHINE RULE -- MAC ONLY TRADES LIVE (ez_manage / tradier_manage) AND NEVER TESTS. MAC has 5 NPZs and NO NVDA.npz / NO CRWD.npz → any S1 vector returns 'no NPZ' in 0.2s. S1 = 157.180.125.52 (s1-int via gateway 157.90.168.35) has 1000+ NPZs (42-49M) and is ONLY test host (S2 for mega sweeps only). If on MacBook, SSH FIRST: ssh 157.180.125.52 OR ssh -fNT s1-sftp && ssh s1-int. Verify: ls /home/niels/binance-sandbox/backtest_v8/indicators/NVDA.npz must exist. If not, STOP.
A3: ⚠️ SYNC & BACKUP RULE -- KEEP ALL FIXES synced Mac <-> S1 via rsync -avz -e 'ssh -p 2201' and KEEP BACKUPS before EVERY edit: cp <file> backups/before_<desc>_$(date +%Y%m%d%H%M).py . Autosave launchd commits git every 15min. /backups/ ONLY reliable history. After BACKTEST_BIBLE.md edit run tools/sync_backtest_bible.sh (SHA256). NEVER edit S1 copy directly without rsync back.
A4: ⚠️ INSTRUCTIONS ARE LAW — v12_pilot.py MUST READ THIS TAB AT STARTUP. DEPRECATED 2026-09-11: v12_pilot_sheet_runner.py / v14_sequential_filler.py are DISABLED (empty L:BI, 408-row waste). CORRECT PIPELINE: tools/simple_switch_filter_calculator.py (26-col, 9291×26, resumable, <0.7s/NPZ) → data/reports/BNB_GLD_FULL_*.csv → tools/fill_template_from_csv.py → SPREADSHEETS/TEMPLATE_*_FILLED.xlsx (BASELINE + Results 9291 + L:IL 6503). This tab wins over code if conflict.
A5: 0) PRECONDITION -- DO NOT START UNTIL DEFAULTS ARE BOLD. Every row where B == live default (config.py Config for crypto / config_tradier.py TradierConfig for stocks = 1118 fields) must have A and B bold. ~50% rows bold. NEVER edit B (candidate value in col B). You only write C (override), E (baseline gain), F (delta vs E), G (variant gain), and L:BI per-filter deltas.
A6: 1) CREATE BASELINE WITH per_sym OVERRIDES for EXACT sym_side. GET OVERRIDES = union of data/hourly_reconfig/trb/active_config.json AND data/hourly_reconfig/per_sym_active_config.json for YOUR EXACT SYM_SIDE (SYMBOL+_LONG vs _SHORT are DIFFERENT, NEVER reuse). Example NVDA_LONG 8 overrides (BOUNCE_AUGMENT...), CRWD_SHORT 0. For each switch in union, find row where A==switch name and write override into C, BOLD GREEN font 006100 on fill C6EFCE. Do ALL overrides BEFORE baseline calc. Then baseline = vector_evaluate(sym_side, overrides) AND live_evaluate(sym_side, overrides) — they must parity (trades 0.80..1.25, gain 0.5pp|15%, sharpe 0.25). Write TEMPLATE_BASELINE_METRICS!B2 = gain, B? = bh. Verify WT_15M_BOUNCE True adds >100 trades/mo (fix in v12_quick_engine:5894 MAX_BARS_AGO=100). If trades 0 or <30, STOP and spawn agent to fix v12_quick_engine (6817/9010).
A7: 1b) BASELINE E2 = TEMPLATE_BASELINE_METRICS!B2 (gain). E3 = IF(F3>0,E2+F3,"") chain. Never repeat E. First pilot: WT_15M_BOUNCE True must be first positive delta or calculation BROKEN.
A8: 2) FOR EVERY ROW (EVERY SWITCH) TEST EVERY APPLICABLE FILTER × EVERY SETTING. MANDATORY until >100 sym_sides tested (see rule 9). Applicable = FILTER_DICTIONARY_V2 row where (sheets_app contains this tab lifecycle ENTRY/EXIT/REENTRY/AUGMENT/REDUCE or GLOBAL_CHECK) AND (gates token overlap with this switch OR rec is GENERAL). Use get_opportune_filters(switch, sheet) — it already implements this. For WT_15M_BOUNCE_OPEN_ENABLED True you MUST test its 12 sub-filters (BB_MIN 0.05/0.1/0.2, BB_MAX 0.95/0.9/0.8, LOW_1H True/False, HIGH_1H True/False, REL_VOL True/False) even if WT alone delta is NEG — they are FILTERS in FILTER_DICTIONARY, not switches. Do NOT discard. COL J lists per-switch opportune filters (up to 6 shown), COL L:BI holds per-filter deltas (one column per filter=opt).
A9: 2a) EVALUATION: For this row, build candidates: [switch alone] + [switch+each single filter distinct opt (skip opt==cur)] . If best single delta <=0, also test ALL combos of 2 and 3 among top-8 singles (C8,2=28 + C8,3=56 =84 combos). Each candidate = sanitize_overrides(variant, defaults) then vector_evaluate via prepare_batch/evaluate_prepared_sanitized (70-136ms, million/hour). NEVER use per-cell load_npz (3.65s) — use prepare_batch once per sym_side. Log every candidate: [CANDIDATE] switch=cand[+filter=opt] vec_gain delta vs cum trades sharpe. Pick MAX delta (beating-ideas-to-death, not first positive).
A10: 2b) DUPLICATE/0.0 CHECK — Immediately flag DUPLICATE (same delta for 2 different switches → formula bug, e.g. shared adx gate) or 0.0 (dead switch or >5s VECTOR_STALL). If duplicate/0.0, revise v12_quick_engine wiring to exact live numpy (622 not-causal) and run live_evaluate for parity. Fix before promoting.
A11: 2c) PROGRESS REPORT every 5min: count filled F cells per sheet (e.g. NVDA 2790/2823=98.8% — one baseline empty per sheet expected). Write data/reports/lifecycle_pilot/*_pilot_progress.json and SPREADSHEETS/*_pilot_progress.html refreshed 60s. Also log [ROW] sheet!r switch=cand[+filter] delta vs cum -> NEG/POSITIVE candidate.
A12: 3) PROMOTION: Only if best delta >0 AND live_evaluate parity passes (trades 0.80..1.25, gain 0.5pp|15%, sharpe 0.25) AND (vector_only deferred → final cumulative live check). Then write C = cand (bold green 006100 on C6EFCE), cumulative_gain = vec_gain, cumulative_overrides[switch]=cand and if filter best exists also [filter]=fval. Write Results_30d_Deltas row: key=switch=cand, col5=delta, col6=variant_gain, col8=variant_gain, col10=trades, col11=max_dd, col12=tim. Also batch write L:BI deltas for this row (one col per filter=opt = delta). E for this row = IF(F>0,Eprev+F,Eprev) — only F>0 gets bold green E/F/G and C. F/G written even if <=0 for audit, but E stays empty.
... A26: 15) CORRECT PIPELINE 2026-09-11 — S1 ONLY: timeout 1800 python -u tools/simple_switch_filter_calculator.py --symside SYM_SIDE --window-days 30 --max-switches 0 --max-filters 10 → wc -l 9291 26 cols → scp -P 2201 to Mac → python3 tools/fill_template_from_csv.py data/reports/BNB_GLD_FULL_SYM.csv SPREADSHEETS/TEMPLATE_SYM_FILLED.xlsx → verify E3/F3/L3 via openpyxl data_only. See SPREADSHEETS/TEMPLATE_BNBUSDC_LONG_30D_FILLED.xlsx as reference (148,640 Results cells).

Sheet FILTERS_EXPLAINED
A1: Filter | B1: Type | C1: What it does (plain English) | D1: Sheets | E1: Gated Switch | F1: Rec | G1: Tested As | H1: Options | I1: Default | J1: Example
A2: ADX_RANGING_THRESHOLD | B2: Threshold | C2: Blocks signal unless value > threshold (tunable level) | D2: ENTRY, GLOBAL, STOCKS_EXIT | E2: ADX_RANGING_THRESHOL | F2: GENERAL | G2: Blanket (page end) | H2: 20.0, ±25%, ±50% (4) | I2: 20.0 | J2: ADX_RANGING_THRESHOLD=20 -> delta vs cum
A3: ADX_RANGING_THRESHOLD | B3: Threshold | C3: Blocks signal unless value > threshold (tunable level) | D3: ENTRY, GLOBAL, STOCKS_EXIT | E3: ADX_RANGING_THRESHOL | F3: GENERAL | G3: Blanket (page end) | H3: 20.0, ±25%, ±50% (4) | I3: 20.0 | J3: ADX_RANGING_THRESHOLD=25 -> delta vs cum
A4: ADX_RANGING_THRESHOLD | B4: Threshold | C4: Blocks signal unless value > threshold (tunable level) | D4: ENTRY, GLOBAL, STOCKS_EXIT | E4: ADX_RANGING_THRESHOL | F4: GENERAL | G4: Blanket (page end) | H4: 20.0, ±25%, ±50% (4) | I4: 20.0 | J4: ADX_RANGING_THRESHOLD=15 -> delta vs cum
A5: ADX_RANGING_THRESHOLD | B5: Threshold | C5: Blocks signal unless value > threshold (tunable level) | D5: ENTRY, GLOBAL, STOCKS_EXIT | E5: ADX_RANGING_THRESHOL | F5: GENERAL | G5: Blanket (page end) | H5: 20.0, ±25%, ±50% (4) | I5: 20.0 | J5: ADX_RANGING_THRESHOLD=10 -> delta vs cum
A6: ATR_TRAIL_FILTER_TF | B6: MTF Gate | C6: Requires confirmation on multiple timeframes (e.g., 1h+4h) before signal counts | D6: EXIT | E6: ATR trail exits | F6: SPECIFIC — only gate | G6: Per-switch (with switch) | H6: OFF, 15m, 1h, 4h, D (5 options) | I6: 15m | J6: ATR_TRAIL_FILTER_TF=OFF -> delta vs cum
A7: ATR_TRAIL_FILTER_TF | B7: MTF Gate | C7: Requires confirmation on multiple timeframes (e.g., 1h+4h) before signal counts | D7: EXIT | E7: ATR trail exits | F7: SPECIFIC — only gate | G7: Per-switch (with switch) | H7: OFF, 15m, 1h, 4h, D (5 options) | I7: 15m | J7: ATR_TRAIL_FILTER_TF=D -> delta vs cum
A8: ATR_TRAIL_FILTER_TF | B8: MTF Gate | C8: Requires confirmation on multiple timeframes (e.g., 1h+4h) before signal counts | D8: EXIT | E8: ATR trail exits | F8: SPECIFIC — only gate | G8: Per-switch (with switch) | H8: OFF, 15m, 1h, 4h, D (5 options) | I8: 15m | J8: ATR_TRAIL_FILTER_TF=4h -> delta vs cum
A9: ATR_TRAIL_FILTER_TF | B9: MTF Gate | C9: Requires confirmation on multiple timeframes (e.g., 1h+4h) before signal counts | D9: EXIT | E9: ATR trail exits | F9: SPECIFIC — only gate | G9: Per-switch (with switch) | H9: OFF, 15m, 1h, 4h, D (5 options) | I9: 15m | J9: ATR_TRAIL_FILTER_TF=1h -> delta vs cum
A10: ATR_TRAIL_FILTER_TF | B10: MTF Gate | C10: Requires confirmation on multiple timeframes (e.g., 1h+4h) before signal counts | D10: EXIT | E10: ATR trail exits | F10: SPECIFIC — only gate | G10: Per-switch (with switch) | H10: OFF, 15m, 1h, 4h, D (5 options) | I10: 15m | J10: ATR_TRAIL_FILTER_TF=15m -> delta vs cum
A11: BANDAID_OFF_LOSER_RECOVER_PCT | B11: Threshold | C11: Blocks signal unless value > threshold (tunable level) | D11: AUGMENT, ENTRY, EXIT, GLOBAL, | E11: BANDAID_OFF_LOSER_RE | F11: GENERAL | G11: Blanket (page end) | H11: 0.0, ±25%, ±50% (4) | I11: 0.0 | J11: BANDAID_OFF_LOSER_RECOVER_PCT=0 -> delta vs cum
A12: BANDAID_OFF_LOSER_RECOVER_PCT | B12: Threshold | C12: Blocks signal unless value > threshold (tunable level) | D12: AUGMENT, ENTRY, EXIT, GLOBAL, | E12: BANDAID_OFF_LOSER_RE | F12: GENERAL | G12: Blanket (page end) | H12: 0.0, ±25%, ±50% (4) | I12: 0.0 | J12: BANDAID_OFF_LOSER_RECOVER_PCT=2.0 -> delta vs cum
... A303: LR_BAND_LADDER_STOCH_EXTREME | B303: Other | C303: Blocks signal unless value > threshold (tunable level) | D303: GLOBAL, STOCKS_EXIT | E303: LR_BAND_LADDER_STOCH | F303: GENERAL | G303: Blanket (page end) | H303: 30.0, alt | I303: 30.0 | J303: LR_BAND_LADDER_STOCH_EXTREME=30.0_ALT -> delta vs cum
A304: LR_BAND_LADDER_TF_BOTTOM | B304: MTF Gate | C304: Blocks signal unless value > threshold (tunable level) | D304: GLOBAL, STOCKS_EXIT | E304: LR_BAND_LADDER_TF_BO | F304: GENERAL | G304: Blanket (page end) | H304: , alt | J304: LR_BAND_LADDER_TF_BOTTOM=0 -> delta vs cum
A305: LR_BAND_LADDER_TF_BOTTOM | B305: MTF Gate | C305: Blocks signal unless value > threshold (tunable level) | D305: GLOBAL, STOCKS_EXIT | E305: LR_BAND_LADDER_TF_BO | F305: GENERAL | G305: Blanket (page end) | H305: , alt | J305: LR_BAND_LADDER_TF_BOTTOM=1 -> delta vs cum
A306: LR_BAND_LADDER_TF_TOP | B306: MTF Gate | C306: Blocks signal unless value > threshold (tunable level) | D306: GLOBAL, STOCKS_EXIT | E306: LR_BAND_LADDER_TF_TO | F306: GENERAL | G306: Blanket (page end) | H306: , alt | J306: LR_BAND_LADDER_TF_TOP=0 -> delta vs cum
A307: LR_BAND_LADDER_TF_TOP | B307: MTF Gate | C307: Blocks signal unless value > threshold (tunable level) | D307: GLOBAL, STOCKS_EXIT | E307: LR_BAND_LADDER_TF_TO | F307: GENERAL | G307: Blanket (page end) | H307: , alt | J307: LR_BAND_LADDER_TF_TOP=1 -> delta vs cum
A308: MANDATORY_REENTRY_WT_FILTER_MIN_TFS | B308: MTF Gate | C308: Blocks signal unless value > threshold (tunable level) | D308: GLOBAL, STOCKS_EXIT | E308: MANDATORY_REENTRY_WT | F308: GENERAL | G308: Blanket (page end) | H308: 1, +1, +2 (3) | I308: 1 | J308: MANDATORY_REENTRY_WT_FILTER_MIN_TFS=1 -> delta vs cum
A309: MANDATORY_REENTRY_WT_FILTER_MIN_TFS | B309: MTF Gate | C309: Blocks signal unless value > threshold (tunable level) | D309: GLOBAL, STOCKS_EXIT | E309: MANDATORY_REENTRY_WT | F309: GENERAL | G309: Blanket (page end) | H309: 1, +1, +2 (3) | I309: 1 | J309: MANDATORY_REENTRY_WT_FILTER_MIN_TFS=3 -> delta vs cum
A310: MANDATORY_REENTRY_WT_FILTER_MIN_TFS | B310: MTF Gate | C310: Blocks signal unless value > threshold (tunable level) | D310: GLOBAL, STOCKS_EXIT | E310: MANDATORY_REENTRY_WT | F310: GENERAL | G310: Blanket (page end) | H310: 1, +1, +2 (3) | I310: 1 | J310: MANDATORY_REENTRY_WT_FILTER_MIN_TFS=2 -> delta vs cum
A311: MANDATORY_REENTRY_WT_FILTER_MIN_VELOCITY | B311: Other | C311: Blocks signal unless value > threshold (tunable level) | D311: GLOBAL, STOCKS_EXIT | E311: MANDATORY_REENTRY_WT | F311: GENERAL | G311: Blanket (page end) | H311: 0.0, alt | I311: 0.0 | J311: MANDATORY_REENTRY_WT_FILTER_MIN_VELOCITY=0.0 -> delta vs cum
A312: MANDATORY_REENTRY_WT_FILTER_MIN_VELOCITY | B312: Other | C312: Blocks signal unless value > threshold (tunable level) | D312: GLOBAL, STOCKS_EXIT | E312: MANDATORY_REENTRY_WT | F312: GENERAL | G312: Blanket (page end) | H312: 0.0, alt | I312: 0.0 | J312: MANDATORY_REENTRY_WT_FILTER_MIN_VELOCITY=0.0_ALT -> delta vs cum
A313: MANDATORY_REENTRY_WT_FILTER_REQUIRE_FLIP | B313: Other | C313: Blocks signal unless value > threshold (tunable level) | D313: GLOBAL, STOCKS_EXIT | E313: MANDATORY_REENTRY_WT | F313: GENERAL | G313: Blanket (page end) | H313: False, alt | I313: False | J313: MANDATORY_REENTRY_WT_FILTER_REQUIRE_FLIP=False -> delta vs cum
A314: MANDATORY_REENTRY_WT_FILTER_REQUIRE_FLIP | B314: Other | C314: Blocks signal unless value > threshold (tunable level) | D314: GLOBAL, STOCKS_EXIT | E314: MANDATORY_REENTRY_WT | F314: GENERAL | G314: Blanket (page end) | H314: False, alt | I314: False | J314: MANDATORY_REENTRY_WT_FILTER_REQUIRE_FLIP=False_ALT -> delta vs cum
A315: MANDATORY_REENTRY_WT_FILTER_TF_MODE | B315: MTF Gate | C315: WT filter mode for mandatory reentry (e.g. 5m_or_15m). | Live read: `RANTEED_REE | D315: GLOBAL, STOCKS_EXIT | E315: MANDATORY_REENTRY_WT | F315: SPECIFIC — only gate | G315: Per-switch (with switch) | H315: 15m_only, alt | I315: 15m_only | J315: MANDATORY_REENTRY_WT_FILTER_TF_MODE=15m_only -> delta vs cum
A316: MANDATORY_REENTRY_WT_FILTER_TF_MODE | B316: MTF Gate | C316: WT filter mode for mandatory reentry (e.g. 5m_or_15m). | Live read: `RANTEED_REE | D316: GLOBAL, STOCKS_EXIT | E316: MANDATORY_REENTRY_WT | F316: SPECIFIC — only gate | G316: Per-switch (with switch) | H316: 15m_only, alt | I316: 15m_only | J316: MANDATORY_REENTRY_WT_FILTER_TF_MODE=15m_only_ALT -> delta vs cum
A317: MANDATORY_REENTRY_WT_FILTER_VELOCITY_RATIO | B317: Other | C317: Blocks signal unless value > threshold (tunable level) | D317: GLOBAL, STOCKS_EXIT | E317: MANDATORY_REENTRY_WT | F317: GENERAL | G317: Blanket (page end) | H317: 0.90, alt | I317: 0.90 | J317: MANDATORY_REENTRY_WT_FILTER_VELOCITY_RATIO=0.90 -> delta vs cum
A318: MANDATORY_REENTRY_WT_FILTER_VELOCITY_RATIO | B318: Other | C318: Blocks signal unless value > threshold (tunable level) | D318: GLOBAL, STOCKS_EXIT | E318: MANDATORY_REENTRY_WT | F318: GENERAL | G318: Blanket (page end) | H318: 0.90, alt | I318: 0.90 | J318: MANDATORY_REENTRY_WT_FILTER_VELOCITY_RATIO=0.90_ALT -> delta vs cum
A319: MARKET_QUALITY_SCORE_ENABLED | B319: Bool Flag | C319: Market quality score gate (choppiness). | Live read: `'MARKET_QUALITY_SCORE_ENAB | D319: ENTRY, GLOBAL, STOCKS_EXIT | E319: MARKET_QUALITY_SCORE | F319: GENERAL — uniform | G319: Blanket (page end) | H319: False, True (2) | I319: False | J319: MARKET_QUALITY_SCORE_ENABLED=False -> delta vs cum
... A415: PEAK_GIVEBACK_BE_EROSION_FILTER_TF | B415: MTF Gate | C415: Peak giveback / breakeven erosion filter TF. | Live read: `OCH_EXTREME', 'LR_BAN | D415: GLOBAL | E415: PEAK_GIVEBACK_BE_ERO | F415: SPECIFIC — only gate | G415: Per-switch (with switch) | H415: OFF, 15m, 1h, 4h, D (5 options) | I415: 15m | J415: PEAK_GIVEBACK_BE_EROSION_FILTER_TF=15m -> delta vs cum
A416: WT_15M_BOUNCE_BB_MIN | B416: Other | C416: WT 15m bounce: tightens/loosens bounce detection (BB width, vol, prev bar) | D416: REV_BOUNCE | E416: WT_15M_BOUNCE_OPEN_E | F416: SPECIFIC — only gate | G416: Per-switch (with switch) | J416: WT_15M_BOUNCE_BB_MIN=0.05 -> delta vs cum
A417: WT_15M_BOUNCE_BB_MIN | B417: Other | C417: WT 15m bounce: tightens/loosens bounce detection (BB width, vol, prev bar) | D417: REV_BOUNCE | E417: WT_15M_BOUNCE_OPEN_E | F417: SPECIFIC — only gate | G417: Per-switch (with switch) | J417: WT_15M_BOUNCE_BB_MIN=0.1 -> delta vs cum
A418: WT_15M_BOUNCE_BB_MIN | B418: Other | C418: WT 15m bounce: tightens/loosens bounce detection (BB width, vol, prev bar) | D418: REV_BOUNCE | E418: WT_15M_BOUNCE_OPEN_E | F418: SPECIFIC — only gate | G418: Per-switch (with switch) | J418: WT_15M_BOUNCE_BB_MIN=0.2 -> delta vs cum
A419: WT_15M_BOUNCE_BB_MAX | B419: Other | C419: WT 15m bounce: tightens/loosens bounce detection (BB width, vol, prev bar) | D419: REV_BOUNCE | E419: WT_15M_BOUNCE_OPEN_E | F419: SPECIFIC — only gate | G419: Per-switch (with switch) | J419: WT_15M_BOUNCE_BB_MAX=0.95 -> delta vs cum
A420: WT_15M_BOUNCE_BB_MAX | B420: Other | C420: WT 15m bounce: tightens/loosens bounce detection (BB width, vol, prev bar) | D420: REV_BOUNCE | E420: WT_15M_BOUNCE_OPEN_E | F420: SPECIFIC — only gate | G420: Per-switch (with switch) | J420: WT_15M_BOUNCE_BB_MAX=0.9 -> delta vs cum
A421: WT_15M_BOUNCE_BB_MAX | B421: Other | C421: WT 15m bounce: tightens/loosens bounce detection (BB width, vol, prev bar) | D421: REV_BOUNCE | E421: WT_15M_BOUNCE_OPEN_E | F421: SPECIFIC — only gate | G421: Per-switch (with switch) | J421: WT_15M_BOUNCE_BB_MAX=0.8 -> delta vs cum
A422: WT_15M_BOUNCE_LOW_1H_GT_PREV | B422: Other | C422: WT 15m bounce: tightens/loosens bounce detection (BB width, vol, prev bar) | D422: REV_BOUNCE | E422: WT_15M_BOUNCE_OPEN_E | F422: SPECIFIC — only gate | G422: Per-switch (with switch) | J422: WT_15M_BOUNCE_LOW_1H_GT_PREV=True -> delta vs cum
A423: WT_15M_BOUNCE_LOW_1H_GT_PREV | B423: Other | C423: WT 15m bounce: tightens/loosens bounce detection (BB width, vol, prev bar) | D423: REV_BOUNCE | E423: WT_15M_BOUNCE_OPEN_E | F423: SPECIFIC — only gate | G423: Per-switch (with switch) | J423: WT_15M_BOUNCE_LOW_1H_GT_PREV= -> delta vs cum
A424: WT_15M_BOUNCE_HIGH_1H_GT_PREV | B424: Other | C424: WT 15m bounce: tightens/loosens bounce detection (BB width, vol, prev bar) | D424: REV_BOUNCE | E424: WT_15M_BOUNCE_OPEN_E | F424: SPECIFIC — only gate | G424: Per-switch (with switch) | J424: WT_15M_BOUNCE_HIGH_1H_GT_PREV=True -> delta vs cum
A425: WT_15M_BOUNCE_HIGH_1H_GT_PREV | B425: Other | C425: WT 15m bounce: tightens/loosens bounce detection (BB width, vol, prev bar) | D425: REV_BOUNCE | E425: WT_15M_BOUNCE_OPEN_E | F425: SPECIFIC — only gate | G425: Per-switch (with switch) | J425: WT_15M_BOUNCE_HIGH_1H_GT_PREV= -> delta vs cum
...

Sheet INSTRUCTIONS_V2
A1: TEMPLATE_V2_IDEA_GROUPED 231 per-row FULLY CONNECTED 2026-09-08 - every numpy identical to live
A2: Retraced from early today 231 L:IH (TEMPLATE.xlsx 1.7M) - Sep 5 114 per-row was synthetic/disconnected. This file keeps 231 per-row L:IH (every filter TF OFF/D/4h/1h/15m wired).
A3: 01. ENTRY_REVERSAL_BOUNCE - 8 bases -> 21 rows - 231 per-row
A4: 02. ENTRY_BREAKOUT_CHANNEL - 54 bases -> 210 rows - 231 per-row
A5: 03. ENTRY_CONFIRMATION_GATES - 4 bases -> 11 rows - 231 per-row
A6: 04. EXIT_STRUCTURAL - 2 bases -> 6 rows - 231 per-row
A7: 05. EXIT_VELOCITY - 26 bases -> 80 rows - 231 per-row
A8: 06. REENTRY_WINDOWED - 68 bases -> 249 rows - 231 per-row
A9: 07. REENTRY_ADAPTIVE - 10 bases -> 38 rows - 231 per-row
A10: 08. AUGMENT_TREND - 5 bases -> 24 rows - 231 per-row
A11: 09. AUGMENT_RISK_SIZING - 17 bases -> 56 rows - 231 per-row
A12: 10. REDUCE_PROFIT_LOCK - 19 bases -> 53 rows - 231 per-row
... A15: 2026-09-11 UPDATE: See INSTRUCTIONS tab rows 9,12,14 for >100 sym_sides threshold, blanket at end of each tab, and green/blue/darker proven colors. v14 implements get_opportune_filters + 84 combos + blanket GENERAL. ALL filters until 100, then useful per universe.

Sheet ENTRY_REVERSAL_BOUNCE
A1: 01 ENTRY_REVERSAL_BOUNCE - 8 bases -> 21 rows - 231 per-row FULLY CONNECTED
A2: Switch | B2: default | C2: override | D2: Family | E2: BASELINE | F2: VECTOR_DELTA | G2: LIVE_DELTA | H2: LIVE_SHARPE | I2: REAL_COMPLETE | J2: PER_ROW_FILTERS | K2: is_default (backup if bold lost) | L2: ATR_TRAIL_FILTER_TF=OFF | M2: ATR_TRAIL_FILTER_TF=D | N2: ATR_TRAIL_FILTER_TF=4h | O2: ATR_TRAIL_FILTER_TF=1h | P2: ATR_TRAIL_FILTER_TF=15m | Q2: BAR_PATTERNS_FILTER_TF=OFF | R2: BAR_PATTERNS_FILTER_TF=D | S2: BAR_PATTERNS_FILTER_TF=4h | T2: BAR_PATTERNS_FILTER_TF=1h | U2: BAR_PATTERNS_FILTER_TF=15m | V2: BB_PULLBACK_GATE_FILTER_TF=OFF | W2: BB_PULLBACK_GATE_FILTER_TF=D | X2: BB_PULLBACK_GATE_FILTER_TF=4h | Y2: BB_PULLBACK_GATE_FILTER_TF=1h | Z2: BB_PULLBACK_GATE_FILTER_TF=15m | AA2: BB_RECOVERY_ENTRY_FILTER_TF=OFF | AB2: BB_RECOVERY_ENTRY_FILTER_TF=D | AC2: BB_RECOVERY_ENTRY_FILTER_TF=4h | AD2: BB_RECOVERY_ENTRY_FILTER_TF=1h | AE2: BB_RECOVERY_ENTRY_FILTER_TF=15m | AF2: BB_RECOVERY_FILTER_TF=OFF | AG2: BB_RECOVERY_FILTER_TF=D | AH2: BB_RECOVERY_FILTER_TF=4h | AI2: BB_RECOVERY_FILTER_TF=1h | AJ2: BB_RECOVERY_FILTER_TF=15m | AK2: BREAKEVEN_GAIN_EROSION_FILTER_TF=OFF | AL2: BREAKEVEN_GAIN_EROSION_FILTER_TF=D | AM2: BREAKEVEN_GAIN_EROSION_FILTER_TF=4h | AN2: BREAKEVEN_GAIN_EROSION_FILTER_TF=1h | AO2: BREAKEVEN_GAIN_EROSION_FILTER_TF=15m | AP2: BREAKOUT_RETEST_FILTER_TF=OFF | AQ2: BREAKOUT_RETEST_FILTER_TF=D | AR2: BREAKOUT_RETEST_FILTER_TF=4h | AS2: BREAKOUT_RETEST_FILTER_TF=1h | AT2: BREAKOUT_RETEST_FILTER_TF=15m | AU2: BT_WT_CROSS_LADDER_FILTER_TF=OFF | AV2: BT_WT_CROSS_LADDER_FILTER_TF=D | AW2: BT_WT_CROSS_LADDER_FILTER_TF=4h | AX2: BT_WT_CROSS_LADDER_FILTER_TF=1h | AY2: BT_WT_CROSS_LADDER_FILTER_TF=15m | AZ2: CANDLE_PATTERN_STOPS_FILTER_TF=OFF | BA2: CANDLE_PATTERN_STOPS_FILTER_TF=D | BB2: CANDLE_PATTERN_STOPS_FILTER_TF=4h | BC2: CANDLE_PATTERN_STOPS_FILTER_TF=1h | BD2: CANDLE_PATTERN_STOPS_FILTER_TF=15m | BE2: CIRCUIT_SHARPE_GATES_FILTER_TF=OFF | BF2: CIRCUIT_SHARPE_GATES_FILTER_TF=D | BG2: CIRCUIT_SHARPE_GATES_FILTER_TF=4h | BH2: CIRCUIT_SHARPE_GATES_FILTER_TF=1h | BI2: CIRCUIT_SHARPE_GATES_FILTER_TF=15m | BJ2: DC_BREACH_REDUCE_FILTER_TF=OFF | BK2: DC_BREACH_REDUCE_FILTER_TF=D | BL2: DC_BREACH_REDUCE_FILTER_TF=4h | BM2: DC_BREACH_REDUCE_FILTER_TF=1h | BN2: DC_BREACH_REDUCE_FILTER_TF=15m | BO2: DC_BREAK_FILTER_TF=OFF | BP2: DC_BREAK_FILTER_TF=D | BQ2: DC_BREAK_FILTER_TF=4h | BR2: DC_BREAK_FILTER_TF=1h | BS2: DC_BREAK_FILTER_TF=15m | BT2: DC_MOMENTUM_BOTA_SCORER_FILTER_TF=OFF | BU2: DC_MOMENTUM_BOTA_SCORER_FILTER_TF=D | BV2: DC_MOMENTUM_BOTA_SCORER_FILTER_TF=4h | BW2: DC_MOMENTUM_BOTA_SCORER_FILTER_TF=1h | BX2: DC_MOMENTUM_BOTA_SCORER_FILTER_TF=15m | BY2: DELTA_ENGINE_FILTER_TF=OFF | BZ2: DELTA_ENGINE_FILTER_TF=D | CA2: DELTA_ENGINE_FILTER_TF=4h | CB2: DELTA_ENGINE_FILTER_TF=1h | CC2: DELTA_ENGINE_FILTER_TF=15m | CD2: EMA_9_21_FILTER_FILTER_TF=OFF | CE2: EMA_9_21_FILTER_FILTER_TF=D | CF2: EMA_9_21_FILTER_FILTER_TF=4h | CG2: EMA_9_21_FILTER_FILTER_TF=1h | CH2: EMA_9_21_FILTER_FILTER_TF=15m | CI2: EMA_BLANKET_FILTER_FILTER_TF=OFF | CJ2: EMA_BLANKET_FILTER_FILTER_TF=D | CK2: EMA_BLANKET_FILTER_FILTER_TF=4h | CL2: EMA_BLANKET_FILTER_FILTER_TF=1h | CM2: EMA_BLANKET_FILTER_FILTER_TF=15m | CN2: EMERGENCY_BRAKE_FILTER_TF=OFF | CO2: EMERGENCY_BRAKE_FILTER_TF=D | CP2: EMERGENCY_BRAKE_FILTER_TF=4h | CQ2: EMERGENCY_BRAKE_FILTER_TF=1h | CR2: EMERGENCY_BRAKE_FILTER_TF=15m | CS2: EXIT_R1_R2_FILTER_TF=OFF | CT2: EXIT_R1_R2_FILTER_TF=D | CU2: EXIT_R1_R2_FILTER_TF=4h | CV2: EXIT_R1_R2_FILTER_TF=1h | CW2: EXIT_R1_R2_FILTER_TF=15m | CX2: EXIT_TIGHT_BREAKOUT_SCORER_FILTER_TF=OFF | CY2: EXIT_TIGHT_BREAKOUT_SCORER_FILTER_TF=D | CZ2: EXIT_TIGHT_BREAKOUT_SCORER_FILTER_TF=4h | DA2: EXIT_TIGHT_BREAKOUT_SCORER_FILTER_TF=1h | DB2: EXIT_TIGHT_BREAKOUT_SCORER_FILTER_TF=15m | DC2: EXIT_TOP_FADE_FILTER_TF=OFF | DD2: EXIT_TOP_FADE_FILTER_TF=D | DE2: EXIT_TOP_FADE_FILTER_TF=4h | DF2: EXIT_TOP_FADE_FILTER_TF=1h | DG2: EXIT_TOP_FADE_FILTER_TF=15m | DH2: EXIT_TO_REDUCE_ADAPTER_FILTER_TF=OFF | DI2: EXIT_TO_REDUCE_ADAPTER_FILTER_TF=D | DJ2: EXIT_TO_REDUCE_ADAPTER_FILTER_TF=4h | DK2: EXIT_TO_REDUCE_ADAPTER_FILTER_TF=1h | DL2: EXIT_TO_REDUCE_ADAPTER_FILTER_TF=15m | DM2: FAST_RISER_FILTER_TF=OFF | DN2: FAST_RISER_FILTER_TF=D | DO2: FAST_RISER_FILTER_TF=4h | DP2: FAST_RISER_FILTER_TF=1h | DQ2: FAST_RISER_FILTER_TF=15m | DR2: FH_MOMENTUM_FILTER_TF=OFF | DS2: FH_MOMENTUM_FILTER_TF=D | DT2: FH_MOMENTUM_FILTER_TF=4h | DU2: FH_MOMENTUM_FILTER_TF=1h | DV2: FH_MOMENTUM_FILTER_TF=15m | DW2: FIRST_OPEN_THROTTLE_FILTER_TF=OFF | DX2: FIRST_OPEN_THROTTLE_FILTER_TF=D | DY2: FIRST_OPEN_THROTTLE_FILTER_TF=4h | DZ2: FIRST_OPEN_THROTTLE_FILTER_TF=1h | EA2: FIRST_OPEN_THROTTLE_FILTER_TF=15m | EB2: FROZEN_STOP_FILTER_TF=OFF | EC2: FROZEN_STOP_FILTER_TF=D | ED2: FROZEN_STOP_FILTER_TF=4h | EE2: FROZEN_STOP_FILTER_TF=1h | EF2: FROZEN_STOP_FILTER_TF=15m | EG2: GOLDEN_RULE_ENFORCE_FILTER_TF=OFF | EH2: GOLDEN_RULE_ENFORCE_FILTER_TF=D | EI2: GOLDEN_RULE_ENFORCE_FILTER_TF=4h | EJ2: GOLDEN_RULE_ENFORCE_FILTER_TF=1h | EK2: GOLDEN_RULE_ENFORCE_FILTER_TF=15m | EL2: GOLDEN_RULE_HTF_VOTE_FILTER_TF=OFF | EM2: GOLDEN_RULE_HTF_VOTE_FILTER_TF=D | EN2: GOLDEN_RULE_HTF_VOTE_FILTER_TF=4h | EO2: GOLDEN_RULE_HTF_VOTE_FILTER_TF=1h | EP2: GOLDEN_RULE_HTF_VOTE_FILTER_TF=15m | EQ2: GR_FILTER_VEC_FILTER_TF=OFF | ER2: GR_FILTER_VEC_FILTER_TF=D | ES2: GR_FILTER_VEC_FILTER_TF=4h | ET2: GR_FILTER_VEC_FILTER_TF=1h | EU2: GR_FILTER_VEC_FILTER_TF=15m | EV2: GR_V5_STATE_FILTER_TF=OFF | EW2: GR_V5_STATE_FILTER_TF=D | EX2: GR_V5_STATE_FILTER_TF=4h | EY2: GR_V5_STATE_FILTER_TF=1h | EZ2: GR_V5_STATE_FILTER_TF=15m | FA2: HAIKU_WINNER_FILTER_TF=OFF | FB2: HAIKU_WINNER_FILTER_TF=D | FC2: HAIKU_WINNER_FILTER_TF=4h | FD2: HAIKU_WINNER_FILTER_TF=1h | FE2: HAIKU_WINNER_FILTER_TF=15m | FF2: LH_HL_FILTER_TF_REQ=2 | FG2: LH_HL_FILTER_TF_REQ=2_ALT | FH2: LIVE_ENTRY_ENGINE_FILTER_TF=OFF | FI2: LIVE_ENTRY_ENGINE_FILTER_TF=D | FJ2: LIVE_ENTRY_ENGINE_FILTER_TF=4h | FK2: LIVE_ENTRY_ENGINE_FILTER_TF=1h | FL2: LIVE_ENTRY_ENGINE_FILTER_TF=15m | FM2: LIVE_ONLY_SIGNALS_BATCH5_FILTER_TF=OFF | FN2: LIVE_ONLY_SIGNALS_BATCH5_FILTER_TF=D | FO2: LIVE_ONLY_SIGNALS_BATCH5_FILTER_TF=4h | FP2: LIVE_ONLY_SIGNALS_BATCH5_FILTER_TF=1h | FQ2: LIVE_ONLY_SIGNALS_BATCH5_FILTER_TF=15m | FR2: MANDATORY_REENTRY_WT_FILTER_TF_MODE=15m_only | FS2: MANDATORY_REENTRY_WT_FILTER_TF_MODE=15m_only_ALT | FT2: MOM3_FILTER_TF=OFF | FU2: MOM3_FILTER_TF=D | FV2: MOM3_FILTER_TF=4h | FW2: MOM3_FILTER_TF=1h | FX2: MOM3_FILTER_TF=15m | FY2: MOMENTUM_BREAKOUT_FILTER_TF=OFF | FZ2: MOMENTUM_BREAKOUT_FILTER_TF=D | GA2: MOMENTUM_BREAKOUT_FILTER_TF=4h | GB2: MOMENTUM_BREAKOUT_FILTER_TF=1h | GC2: MOMENTUM_BREAKOUT_FILTER_TF=15m | GD2: MTF_ARMED_ENTRIES_FILTER_TF=OFF | GE2: MTF_ARMED_ENTRIES_FILTER_TF=D | GF2: MTF_ARMED_ENTRIES_FILTER_TF=4h | GG2: MTF_ARMED_ENTRIES_FILTER_TF=1h | GH2: MTF_ARMED_ENTRIES_FILTER_TF=15m | GI2: MTF_ATR_TRAIL_FILTER_TF=OFF | GJ2: MTF_ATR_TRAIL_FILTER_TF=D | GK2: MTF_ATR_TRAIL_FILTER_TF=4h | GL2: MTF_ATR_TRAIL_FILTER_TF=1h | GM2: MTF_ATR_TRAIL_FILTER_TF=15m | GN2: MTF_DC_REJECT_FILTER_TF=OFF | GO2: MTF_DC_REJECT_FILTER_TF=D | GP2: MTF_DC_REJECT_FILTER_TF=4h | GQ2: MTF_DC_REJECT_FILTER_TF=1h | GR2: MTF_DC_REJECT_FILTER_TF=15m | GS2: NEWBORN_LOSS_KILL_FILTER_TF=OFF | GT2: NEWBORN_LOSS_KILL_FILTER_TF=D | GU2: NEWBORN_LOSS_KILL_FILTER_TF=4h | GV2: NEWBORN_LOSS_KILL_FILTER_TF=1h | GW2: NEWBORN_LOSS_KILL_FILTER_TF=15m | GX2: NEWBORN_PROTECT_FILTER_TF=OFF | GY2: NEWBORN_PROTECT_FILTER_TF=D | GZ2: NEWBORN_PROTECT_FILTER_TF=4h | HA2: NEWBORN_PROTECT_FILTER_TF=1h | HB2: NEWBORN_PROTECT_FILTER_TF=15m | HC2: NOLOSS_BYPASS_WT5OF5_FILTER_TF=OFF | HD2: NOLOSS_BYPASS_WT5OF5_FILTER_TF=D | HE2: NOLOSS_BYPASS_WT5OF5_FILTER_TF=4h | HF2: NOLOSS_BYPASS_WT5OF5_FILTER_TF=1h | HG2: NOLOSS_BYPASS_WT5OF5_FILTER_TF=15m | HH2: OPEN_INTENT_SIZE_GATES_FILTER_TF=OFF | HI2: OPEN_INTENT_SIZE_GATES_FILTER_TF=D | HJ2: OPEN_INTENT_SIZE_GATES_FILTER_TF=4h | HK2: OPEN_INTENT_SIZE_GATES_FILTER_TF=1h | HL2: OPEN_INTENT_SIZE_GATES_FILTER_TF=15m | HM2: PARTIAL_PROFIT_LOCK_V2_FILTER_TF=OFF | HN2: PARTIAL_PROFIT_LOCK_V2_FILTER_TF=D | HO2: PARTIAL_PROFIT_LOCK_V2_FILTER_TF=4h | HP2: PARTIAL_PROFIT_LOCK_V2_FILTER_TF=1h | HQ2: PARTIAL_PROFIT_LOCK_V2_FILTER_TF=15m | HR2: PEAK_GIVEBACK_BE_EROSION_FILTER_TF=OFF | HS2: PEAK_GIVEBACK_BE_EROSION_FILTER_TF=D | HT2: PEAK_GIVEBACK_BE_EROSION_FILTER_TF=4h | HU2: PEAK_GIVEBACK_BE_EROSION_FILTER_TF=1h | HV2: PEAK_GIVEBACK_BE_EROSION_FILTER_TF=15m | HW2: WT_15M_BOUNCE_BB_MAX=0.95 | HX2: WT_15M_BOUNCE_BB_MAX=0.9 | HY2: WT_15M_BOUNCE_BB_MAX=0.8 | HZ2: WT_15M_BOUNCE_BB_MIN=0.05 | IA2: WT_15M_BOUNCE_BB_MIN=0.1 | IB2: WT_15M_BOUNCE_BB_MIN=0.2 | IC2: WT_15M_BOUNCE_HIGH_1H_GT_PREV=True | ID2: WT_15M_BOUNCE_HIGH_1H_GT_PREV=False | IE2: WT_15M_BOUNCE_LOW_1H_GT_PREV=True | IF2: WT_15M_BOUNCE_LOW_1H_GT_PREV=False | IG2: WT_15M_BOUNCE_REL_VOL_GT_1=True | IH2: WT_15M_BOUNCE_REL_VOL_GT_1=False | II2: Live Location | IJ2: Vec Hook | IK2: Type | IL2: Correct Options
A3: WT_15M_BOUNCE_OPEN_ENABLED | B3: False | C3: WT_15M_BOUNCE_OPEN_ENABLED=False + WT_15M_BOUNCE_BB_MAX=0.8 + BB_WT_TF=15m + GR=18 + BB_RECOVERY_FILTER_TF=OFF + DC_BREAK_FILTER_TF=1h | E3: 19.6481 | F3: 35.5836 | G3: =IFERROR(VLOOKUP($A3,Results_30d_Deltas!$A$2:$H$5000,7,FALSE)-E3,"") | H3: =IFERROR(VLOOKUP($A3,Results_30d_Deltas!$A$2:$H$5000,6,FALSE),"") | K3: =IF(B3=C3,"YES","NO") | IJ3: ez_manage.py:6076 top() | IK3: v12_quick_engine.py:4288 x7
A4: WT_15M_BOUNCE_OPEN_ENABLED | B4: True | E4: -13.3501 | F4: 2.5853 | G4: =IFERROR(VLOOKUP($A4,Results_30d_Deltas!$A$2:$H$5000,7,FALSE)-E3,"") | H4: =IFERROR(VLOOKUP($A4,Results_30d_Deltas!$A$2:$H$5000,6,FALSE),"") | K4: =IF(B4=C4,"YES","NO") | IJ4: ez_manage.py:6076 top() | IK4: v12_quick_engine.py:4288 x7
A5: BB_SQUEEZE_ENTRY_ENABLED | B5: True | E5: -13.3501 | F5: 2.5853 | G5: =IFERROR(VLOOKUP($A5,Results_30d_Deltas!$A$2:$H$5000,7,FALSE)-E4,"") | H5: =IFERROR(VLOOKUP($A5,Results_30d_Deltas!$A$2:$H$5000,6,FALSE),"") | K5: =IF(B5=C5,"YES","NO") | IJ5: ez_manage.py:4371 top() | IK5: v12_quick_engine.py:889 x9
A6: BB_PULLBACK_GATE_TF | B6: OFF | E6: -12.1759 | F6: 3.7596 | G6: =IFERROR(VLOOKUP($A6,Results_30d_Deltas!$A$2:$H$5000,7,FALSE)-E5,"") | H6: =IFERROR(VLOOKUP($A6,Results_30d_Deltas!$A$2:$H$5000,6,FALSE),"") | K6: =IF(B6=C6,"YES","NO") | V6: 2.1874 | W6: 3.7596 | X6: 0.8638 | IJ6: ez_manage.py:4361 top() | IK6: v12_quick_engine.py:288 x12
A7: BB_PULLBACK_GATE_TF | B7: D | E7: -12.1759 | F7: 3.7596 | G7: =IFERROR(VLOOKUP($A7,Results_30d_Deltas!$A$2:$H$5000,7,FALSE)-E6,"") | H7: =IFERROR(VLOOKUP($A7,Results_30d_Deltas!$A$2:$H$5000,6,FALSE),"") | K7: =IF(B7=C7,"YES","NO") | V7: 2.1874 | W7: 3.7596 | X7: 0.8638 | IJ7: ez_manage.py:4361 top() | IK7: v12_quick_engine.py:288 x12
A8: BB_PULLBACK_GATE_TF | B8: 4h | E8: -12.1759 | F8: 3.7596 | G8: =IFERROR(VLOOKUP($A8,Results_30d_Deltas!$A$2:$H$5000,7,FALSE)-E7,"") | H8: =IFERROR(VLOOKUP($A8,Results_30d_Deltas!$A$2:$H$5000,6,FALSE),"") | K8: =IF(B8=C8,"YES","NO") | V8: 2.1874 | W8: 3.7596 | X8: 0.8638 | IJ8: ez_manage.py:4361 top() | IK8: v12_quick_engine.py:288 x12
A9: BB_PULLBACK_GATE_TF | B9: 1h | E9: -12.1759 | F9: 3.7596 | G9: =IFERROR(VLOOKUP($A9,Results_30d_Deltas!$A$2:$H$5000,7,FALSE)-E8,"") | H9: =IFERROR(VLOOKUP($A9,Results_30d_Deltas!$A$2:$H$5000,6,FALSE),"") | K9: =IF(B9=C9,"YES","NO") | V9: 2.1874 | W9: 3.7596 | X9: 0.8638 | IJ9: ez_manage.py:4361 top() | IK9: v12_quick_engine.py:288 x12
A10: BB_PULLBACK_GATE_TF | B10: 15m | E10: -12.1759 | F10: 3.7596 | G10: =IFERROR(VLOOKUP($A10,Results_30d_Deltas!$A$2:$H$5000,7,FALSE)-E9,"") | H10: =IFERROR(VLOOKUP($A10,Results_30d_Deltas!$A$2:$H$5000,6,FALSE),"") | K10: =IF(B10=C10,"YES","NO") | V10: 2.1874 | W10: 3.7596 | X10: 0.8638 | IJ10: ez_manage.py:4361 top() | IK10: v12_quick_engine.py:288 x12
A11: DELTA_GATE_BB_SQUEEZE | B11: True | E11: -12.1759 | F11: 3.7596 | G11: =IFERROR(VLOOKUP($A11,Results_30d_Deltas!$A$2:$H$5000,7,FALSE)-E10,"") | H11: =IFERROR(VLOOKUP($A11,Results_30d_Deltas!$A$2:$H$5000,6,FALSE),"") | K11: =IF(B11=C11,"YES","NO") | IJ11: ez_manage.py:4603 top() | IK11: v12_quick_engine.py:969 x9
A12: BB_SQUEEZE_WIDTH_PERCENTILE | B12: 0.1 | E12: -13.3501 | F12: 2.5853 | G12: =IFERROR(VLOOKUP($A12,Results_30d_Deltas!$A$2:$H$5000,7,FALSE)-E11,"") | H12: =IFERROR(VLOOKUP($A12,Results_30d_Deltas!$A$2:$H$5000,6,FALSE),"") | K12: =IF(B12=C12,"YES","NO") | IJ12: ez_manage.py:4375 top() | IK12: v12_quick_engine.py:1285 x7
A13: BB_SQUEEZE_WIDTH_PERCENTILE | B13: 0.15 | E13: -13.3501 | F13: 2.5853 | G13: =IFERROR(VLOOKUP($A13,Results_30d_Deltas!$A$2:$H$5000,7,FALSE)-E12,"") | H13: =IFERROR(VLOOKUP($A13,Results_30d_Deltas!$A$2:$H$5000,6,FALSE),"") | K13: =IF(B13=C13,"YES","NO") | IJ13: ez_manage.py:4375 top() | IK13: v12_quick_engine.py:1285 x7
A14: BB_SQUEEZE_WIDTH_PERCENTILE | B14: 0.2 | E14: -13.3501 | F14: 2.5853 | G14: =IFERROR(VLOOKUP($A14,Results_30d_Deltas!$A$2:$H$5000,7,FALSE)-E13,"") | H14: =IFERROR(VLOOKUP($A14,Results_30d_Deltas!$A$2:$H$5000,6,FALSE),"") | K14: =IF(B14=C14,"YES","NO") | IJ14: ez_manage.py:4375 top() | IK14: v12_quick_engine.py:1285 x7
A15: BB_SQUEEZE_WIDTH_PERCENTILE | B15: 0.25 | E15: -13.3501 | F15: 2.5853 | G15: =IFERROR(VLOOKUP($A15,Results_30d_Deltas!$A$2:$H$5000,7,FALSE)-E14,"") | H15: =IFERROR(VLOOKUP($A15,Results_30d_Deltas!$A$2:$H$5000,6,FALSE),"") | K15: =IF(B15=C15,"YES","NO") | IJ15: ez_manage.py:4375 top() | IK15: v12_quick_engine.py:1285 x7
A16: BB_SQUEEZE_WIDTH_PERCENTILE | B16: 0.3 | E16: -13.3501 | F16: 2.5853 | G16: =IFERROR(VLOOKUP($A16,Results_30d_Deltas!$A$2:$H$5000,7,FALSE)-E15,"") | H16: =IFERROR(VLOOKUP($A16,Results_30d_Deltas!$A$2:$H$5000,6,FALSE),"") | K16: =IF(B16=C16,"YES","NO") | IJ16: ez_manage.py:4375 top() | IK16: v12_quick_engine.py:1285 x7
A17: WT_DIV_EXIT_ENABLED | B17: False | E17: -13.3501 | F17: 2.5853 | G17: =IFERROR(VLOOKUP($A17,Results_30d_Deltas!$A$2:$H$5000,7,FALSE)-E16,"") | H17: =IFERROR(VLOOKUP($A17,Results_30d_Deltas!$A$2:$H$5000,6,FALSE),"") | K17: =IF(B17=C17,"YES","NO") | IJ17: ez_manage.py:6086 top() | IK17: v12_quick_engine.py:4292 x3
A18: WT_DIV_EXIT_ENABLED | B18: True | E18: -12.1759 | F18: 3.7596 | G18: =IFERROR(VLOOKUP($A18,Results_30d_Deltas!$A$2:$H$5000,7,FALSE)-E17,"") | H18: =IFERROR(VLOOKUP($A18,Results_30d_Deltas!$A$2:$H$5000,6,FALSE),"") | K18: =IF(B18=C18,"YES","NO") | IJ18: ez_manage.py:6086 top() | IK18: v12_quick_engine.py:4292 x3
A19: WT_MOMENTUM_EXIT_THRESHOLD | B19: 0 | E19: -13.3501 | F19: 2.5853 | G19: =IFERROR(VLOOKUP($A19,Results_30d_Deltas!$A$2:$H$5000,7,FALSE)-E18,"") | H19: =IFERROR(VLOOKUP($A19,Results_30d_Deltas!$A$2:$H$5000,6,FALSE),"") | K19: =IF(B19=C19,"YES","NO") | IJ19: ez_manage.py:6087 top() | IK19: v12_quick_engine.py:4293 x3
A20: WT_MOMENTUM_EXIT_THRESHOLD | B20: 1 | E20: -13.3501 | F20: 2.5853 | G20: =IFERROR(VLOOKUP($A20,Results_30d_Deltas!$A$2:$H$5000,7,FALSE)-E19,"") | H20: =IFERROR(VLOOKUP($A20,Results_30d_Deltas!$A$2:$H$5000,6,FALSE),"") | K20: =IF(B20=C20,"YES","NO") | IJ20: ez_manage.py:6087 top() | IK20: v12_quick_engine.py:4293 x3
A21: WT_MOMENTUM_EXIT_THRESHOLD | B21: 2 | E21: -13.3501 | F21: 2.5853 | G21: =IFERROR(VLOOKUP($A21,Results_30d_Deltas!$A$2:$H$5000,7,FALSE)-E20,"") | H21: =IFERROR(VLOOKUP($A21,Results_30d_Deltas!$A$2:$H$5000,6,FALSE),"") | K21: =IF(B21=C21,"YES","NO") | IJ21: ez_manage.py:6087 top() | IK21: v12_quick_engine.py:4293 x3
A22: WT_ACCEL_EXIT_ENABLED | B22: False | E22: -13.3501 | F22: 2.5853 | G22: =IFERROR(VLOOKUP($A22,Results_30d_Deltas!$A$2:$H$5000,7,FALSE)-E21,"") | H22: =IFERROR(VLOOKUP($A22,Results_30d_Deltas!$A$2:$H$5000,6,FALSE),"") | K22: =IF(B22=C22,"YES","NO") | IJ22: ez_manage.py:6083 top() | IK22: v12_quick_engine.py:4290 x3
A23: WT_ACCEL_EXIT_ENABLED | B23: True | E23: -13.748 | F23: 2.1874 | G23: =IFERROR(VLOOKUP($A23,Results_30d_Deltas!$A$2:$H$5000,7,FALSE)-E22,"") | H23: =IFERROR(VLOOKUP($A23,Results_30d_Deltas!$A$2:$H$5000,6,FALSE),"") | K23: =IF(B23=C23,"YES","NO") | IJ23: ez_manage.py:6083 top() | IK23: v12_quick_engine.py:4290 x3

Sheet ENTRY_BREAKOUT_CHANNEL
A1: 02 ENTRY_BREAKOUT_CHANNEL - 54 bases -> 210 rows - 231 per-row FULLY CONNECTED
A2: Switch | B2: default | C2: override | D2: Family | E2: BASELINE | F2: VECTOR_DELTA | G2: LIVE_DELTA | H2: LIVE_SHARPE | I2: REAL_COMPLETE | J2: PER_ROW_FILTERS | K2: is_default (backup if bold lost) | L2: ATR_TRAIL_FILTER_TF=OFF | M2: ATR_TRAIL_FILTER_TF=D | N2: ATR_TRAIL_FILTER_TF=4h | O2: ATR_TRAIL_FILTER_TF=1h | P2: ATR_TRAIL_FILTER_TF=15m | Q2: BAR_PATTERNS_FILTER_TF=OFF | R2: BAR_PATTERNS_FILTER_TF=D | S2: BAR_PATTERNS_FILTER_TF=4h | T2: BAR_PATTERNS_FILTER_TF=1h | U2: BAR_PATTERNS_FILTER_TF=15m | V2: BB_PULLBACK_GATE_FILTER_TF=OFF | W2: BB_PULLBACK_GATE_FILTER_TF=D | X2: BB_PULLBACK_GATE_FILTER_TF=4h | Y2: BB_PULLBACK_GATE_FILTER_TF=1h | Z2: BB_PULLBACK_GATE_FILTER_TF=15m | AA2: BB_RECOVERY_ENTRY_FILTER_TF=OFF | AB2: BB_RECOVERY_ENTRY_FILTER_TF=D | AC2: BB_RECOVERY_ENTRY_FILTER_TF=4h | AD2: BB_RECOVERY_ENTRY_FILTER_TF=1h | AE2: BB_RECOVERY_ENTRY_FILTER_TF=15m | AF2: BB_RECOVERY_FILTER_TF=OFF | AG2: BB_RECOVERY_FILTER_TF=D | AH2: BB_RECOVERY_FILTER_TF=4h | AI2: BB_RECOVERY_FILTER_TF=1h | AJ2: BB_RECOVERY_FILTER_TF=15m | AK2: BREAKEVEN_GAIN_EROSION_FILTER_TF=OFF | AL2: BREAKEVEN_GAIN_EROSION_FILTER_TF=D | AM2: BREAKEVEN_GAIN_EROSION_FILTER_TF=4h | AN2: BREAKEVEN_GAIN_EROSION_FILTER_TF=1h | AO2: BREAKEVEN_GAIN_EROSION_FILTER_TF=15m | AP2: BREAKOUT_RETEST_FILTER_TF=OFF | AQ2: BREAKOUT_RETEST_FILTER_TF=D | AR2: BREAKOUT_RETEST_FILTER_TF=4h | AS2: BREAKOUT_RETEST_FILTER_TF=1h | AT2: BREAKOUT_RETEST_FILTER_TF=15m | AU2: BT_WT_CROSS_LADDER_FILTER_TF=OFF | AV2: BT_WT_CROSS_LADDER_FILTER_TF=D | AW2: BT_WT_CROSS_LADDER_FILTER_TF=4h | AX2: BT_WT_CROSS_LADDER_FILTER_TF=1h | AY2: BT_WT_CROSS_LADDER_FILTER_TF=15m | AZ2: CANDLE_PATTERN_STOPS_FILTER_TF=OFF | BA2: CANDLE_PATTERN_STOPS_FILTER_TF=D | BB2: CANDLE_PATTERN_STOPS_FILTER_TF=4h | BC2: CANDLE_PATTERN_STOPS_FILTER_TF=1h | BD2: CANDLE_PATTERN_STOPS_FILTER_TF=15m | BE2: CIRCUIT_SHARPE_GATES_FILTER_TF=OFF | BF2: CIRCUIT_SHARPE_GATES_FILTER_TF=D | BG2: CIRCUIT_SHARPE_GATES_FILTER_TF=4h | BH2: CIRCUIT_SHARPE_GATES_FILTER_TF=1h | BI2: CIRCUIT_SHARPE_GATES_FILTER_TF=15m | BJ2: DC_BREACH_REDUCE_FILTER_TF=OFF | BK2: DC_BREACH_REDUCE_FILTER_TF=D | BL2: DC_BREACH_REDUCE_FILTER_TF=4h | BM2: DC_BREACH_REDUCE_FILTER_TF=1h | BN2: DC_BREACH_REDUCE_FILTER_TF=15m | BO2: DC_BREAK_FILTER_TF=OFF | BP2: DC_BREAK_FILTER_TF=D | BQ2: DC_BREAK_FILTER_TF=4h | BR2: DC_BREAK_FILTER_TF=1h | BS2: DC_BREAK_FILTER_TF=15m | BT2: DC_MOMENTUM_BOTA_SCORER_FILTER_TF=OFF | BU2: DC_MOMENTUM_BOTA_SCORER_FILTER_TF=D | BV2: DC_MOMENTUM_BOTA_SCORER_FILTER_TF=4h | BW2: DC_MOMENTUM_BOTA_SCORER_FILTER_TF=1h | BX2: DC_MOMENTUM_BOTA_SCORER_FILTER_TF=15m | BY2: DELTA_ENGINE_FILTER_TF=OFF | BZ2: DELTA_ENGINE_FILTER_TF=D | CA2: DELTA_ENGINE_FILTER_TF=4h | CB2: DELTA_ENGINE_FILTER_TF=1h | CC2: DELTA_ENGINE_FILTER_TF=15m | CD2: EMA_9_21_FILTER_FILTER_TF=OFF | CE2: EMA_9_21_FILTER_FILTER_TF=D | CF2: EMA_9_21_FILTER_FILTER_TF=4h | CG2: EMA_9_21_FILTER_FILTER_TF=1h | CH2: EMA_9_21_FILTER_FILTER_TF=15m | CI2: EMA_BLANKET_FILTER_FILTER_TF=OFF | CJ2: EMA_BLANKET_FILTER_FILTER_TF=D | CK2: EMA_BLANKET_FILTER_FILTER_TF=4h | CL2: EMA_BLANKET_FILTER_FILTER_TF=1h | CM2: EMA_BLANKET_FILTER_FILTER_TF=15m | CN2: EMERGENCY_BRAKE_FILTER_TF=OFF | CO2: EMERGENCY_BRAKE_FILTER_TF=D | CP2: EMERGENCY_BRAKE_FILTER_TF=4h | CQ2: EMERGENCY_BRAKE_FILTER_TF=1h | CR2: EMERGENCY_BRAKE_FILTER_TF=15m | CS2: EXIT_R1_R2_FILTER_TF=OFF | CT2: EXIT_R1_R2_FILTER_TF=D | CU2: EXIT_R1_R2_FILTER_TF=4h | CV2: EXIT_R1_R2_FILTER_TF=1h | CW2: EXIT_R1_R2_FILTER_TF=15m | CX2: EXIT_TIGHT_BREAKOUT_SCORER_FILTER_TF=OFF | CY2: EXIT_TIGHT_BREAKOUT_SCORER_FILTER_TF=D | CZ2: EXIT_TIGHT_BREAKOUT_SCORER_FILTER_TF=4h | DA2: EXIT_TIGHT_BREAKOUT_SCORER_FILTER_TF=1h | DB2: EXIT_TIGHT_BREAKOUT_SCORER_FILTER_TF=15m | DC2: EXIT_TOP_FADE_FILTER_TF=OFF | DD2: EXIT_TOP_FADE_FILTER_TF=D | DE2: EXIT_TOP_FADE_FILTER_TF=4h | DF2: EXIT_TOP_FADE_FILTER_TF=1h | DG2: EXIT_TOP_FADE_FILTER_TF=15m | DH2: EXIT_TO_REDUCE_ADAPTER_FILTER_TF=OFF | DI2: EXIT_TO_REDUCE_ADAPTER_FILTER_TF=D | DJ2: EXIT_TO_REDUCE_ADAPTER_FILTER_TF=4h | DK2: EXIT_TO_REDUCE_ADAPTER_FILTER_TF=1h | DL2: EXIT_TO_REDUCE_ADAPTER_FILTER_TF=15m | DM2: FAST_RISER_FILTER_TF=OFF | DN2: FAST_RISER_FILTER_TF=D | DO2: FAST_RISER_FILTER_TF=4h | DP2: FAST_RISER_FILTER_TF=1h | DQ2: FAST_RISER_FILTER_TF=15m | DR2: FH_MOMENTUM_FILTER_TF=OFF | DS2: FH_MOMENTUM_FILTER_TF=D | DT2: FH_MOMENTUM_FILTER_TF=4h | DU2: FH_MOMENTUM_FILTER_TF=1h | DV2: FH_MOMENTUM_FILTER_TF=15m | DW2: FIRST_OPEN_THROTTLE_FILTER_TF=OFF | DX2: FIRST_OPEN_THROTTLE_FILTER_TF=D | DY2: FIRST_OPEN_THROTTLE_FILTER_TF=4h | DZ2: FIRST_OPEN_THROTTLE_FILTER_TF=1h | EA2: FIRST_OPEN_THROTTLE_FILTER_TF=15m | EB2: FROZEN_STOP_FILTER_TF=OFF | EC2: FROZEN_STOP_FILTER_TF=D | ED2: FROZEN_STOP_FILTER_TF=4h | EE2: FROZEN_STOP_FILTER_TF=1h | EF2: FROZEN_STOP_FILTER_TF=15m | EG2: GOLDEN_RULE_ENFORCE_FILTER_TF=OFF | EH2: GOLDEN_RULE_ENFORCE_FILTER_TF=D | EI2: GOLDEN_RULE_ENFORCE_FILTER_TF=4h | EJ2: GOLDEN_RULE_ENFORCE_FILTER_TF=1h | EK2: GOLDEN_RULE_ENFORCE_FILTER_TF=15m | EL2: GOLDEN_RULE_HTF_VOTE_FILTER_TF=OFF | EM2: GOLDEN_RULE_HTF_VOTE_FILTER_TF=D | EN2: GOLDEN_RULE_HTF_VOTE_FILTER_TF=4h | EO2: GOLDEN_RULE_HTF_VOTE_FILTER_TF=1h | EP2: GOLDEN_RULE_HTF_VOTE_FILTER_TF=15m | EQ2: GR_FILTER_VEC_FILTER_TF=OFF | ER2: GR_FILTER_VEC_FILTER_TF=D | ES2: GR_FILTER_VEC_FILTER_TF=4h | ET2: GR_FILTER_VEC_FILTER_TF=1h | EU2: GR_FILTER_VEC_FILTER_TF=15m | EV2: GR_V5_STATE_FILTER_TF=OFF | EW2: GR_V5_STATE_FILTER_TF=D | EX2: GR_V5_STATE_FILTER_TF=4h | EY2: GR_V5_STATE_FILTER_TF=1h | EZ2: GR_V5_STATE_FILTER_TF=15m | FA2: HAIKU_WINNER_FILTER_TF=OFF | FB2: HAIKU_WINNER_FILTER_TF=D | FC2: HAIKU_WINNER_FILTER_TF=4h | FD2: HAIKU_WINNER_FILTER_TF=1h | FE2: HAIKU_WINNER_FILTER_TF=15m | FF2: LH_HL_FILTER_TF_REQ=2 | FG2: LH_HL_FILTER_TF_REQ=2_ALT | FH2: LIVE_ENTRY_ENGINE_FILTER_TF=OFF | FI2: LIVE_ENTRY_ENGINE_FILTER_TF=D | FJ2: LIVE_ENTRY_ENGINE_FILTER_TF=4h | FK2: LIVE_ENTRY_ENGINE_FILTER_TF=1h | FL2: LIVE_ENTRY_ENGINE_FILTER_TF=15m | FM2: LIVE_ONLY_SIGNALS_BATCH5_FILTER_TF=OFF | FN2: LIVE_ONLY_SIGNALS_BATCH5_FILTER_TF=D | FO2: LIVE_ONLY_SIGNALS_BATCH5_FILTER_TF=4h | FP2: LIVE_ONLY_SIGNALS_BATCH5_FILTER_TF=1h | FQ2: LIVE_ONLY_SIGNALS_BATCH5_FILTER_TF=15m | FR2: MANDATORY_REENTRY_WT_FILTER_TF_MODE=15m_only | FS2: MANDATORY_REENTRY_WT_FILTER_TF_MODE=15m_only_ALT | FT2: MOM3_FILTER_TF=OFF | FU2: MOM3_FILTER_TF=D | FV2: MOM3_FILTER_TF=4h | FW2: MOM3_FILTER_TF=1h | FX2: MOM3_FILTER_TF=15m | FY2: MOMENTUM_BREAKOUT_FILTER_TF=OFF | FZ2: MOMENTUM_BREAKOUT_FILTER_TF=D | GA2: MOMENTUM_BREAKOUT_FILTER_TF=4h | GB2: MOMENTUM_BREAKOUT_FILTER_TF=1h | GC2: MOMENTUM_BREAKOUT_FILTER_TF=15m | GD2: MTF_ARMED_ENTRIES_FILTER_TF=OFF | GE2: MTF_ARMED_ENTRIES_FILTER_TF=D | GF2: MTF_ARMED_ENTRIES_FILTER_TF=4h | GG2: MTF_ARMED_ENTRIES_FILTER_TF=1h | GH2: MTF_ARMED_ENTRIES_FILTER_TF=15m | GI2: MTF_ATR_TRAIL_FILTER_TF=OFF | GJ2: MTF_ATR_TRAIL_FILTER_TF=D | GK2: MTF_ATR_TRAIL_FILTER_TF=4h | GL2: MTF_ATR_TRAIL_FILTER_TF=1h | GM2: MTF_ATR_TRAIL_FILTER_TF=15m | GN2: MTF_DC_REJECT_FILTER_TF=OFF | GO2: MTF_DC_REJECT_FILTER_TF=D | GP2: MTF_DC_REJECT_FILTER_TF=4h | GQ2: MTF_DC_REJECT_FILTER_TF=1h | GR2: MTF_DC_REJECT_FILTER_TF=15m | GS2: NEWBORN_LOSS_KILL_FILTER_TF=OFF | GT2: NEWBORN_LOSS_KILL_FILTER_TF=D | GU2: NEWBORN_LOSS_KILL_FILTER_TF=4h | GV2: NEWBORN_LOSS_KILL_FILTER_TF=1h | GW2: NEWBORN_LOSS_KILL_FILTER_TF=15m | GX2: NEWBORN_PROTECT_FILTER_TF=OFF | GY2: NEWBORN_PROTECT_FILTER_TF=D | GZ2: NEWBORN_PROTECT_FILTER_TF=4h | HA2: NEWBORN_PROTECT_FILTER_TF=1h | HB2: NEWBORN_PROTECT_FILTER_TF=15m | HC2: NOLOSS_BYPASS_WT5OF5_FILTER_TF=OFF | HD2: NOLOSS_BYPASS_WT5OF5_FILTER_TF=D | HE2: NOLOSS_BYPASS_WT5OF5_FILTER_TF=4h | HF2: NOLOSS_BYPASS_WT5OF5_FILTER_TF=1h | HG2: NOLOSS_BYPASS_WT5OF5_FILTER_TF=15m | HH2: OPEN_INTENT_SIZE_GATES_FILTER_TF=OFF | HI2: OPEN_INTENT_SIZE_GATES_FILTER_TF=D | HJ2: OPEN_INTENT_SIZE_GATES_FILTER_TF=4h | HK2: OPEN_INTENT_SIZE_GATES_FILTER_TF=1h | HL2: OPEN_INTENT_SIZE_GATES_FILTER_TF=15m | HM2: PARTIAL_PROFIT_LOCK_V2_FILTER_TF=OFF | HN2: PARTIAL_PROFIT_LOCK_V2_FILTER_TF=D | HO2: PARTIAL_PROFIT_LOCK_V2_FILTER_TF=4h | HP2: PARTIAL_PROFIT_LOCK_V2_FILTER_TF=1h | HQ2: PARTIAL_PROFIT_LOCK_V2_FILTER_TF=15m | HR2: PEAK_GIVEBACK_BE_EROSION_FILTER_TF=OFF | HS2: PEAK_GIVEBACK_BE_EROSION_FILTER_TF=D | HT2: PEAK_GIVEBACK_BE_EROSION_FILTER_TF=4h | HU2: PEAK_GIVEBACK_BE_EROSION_FILTER_TF=1h | HV2: PEAK_GIVEBACK_BE_EROSION_FILTER_TF=15m | HW2: WT_15M_BOUNCE_BB_MAX=0.95 | HX2: WT_15M_BOUNCE_BB_MAX=0.9 | HY2: WT_15M_BOUNCE_BB_MAX=0.8 | HZ2: WT_15M_BOUNCE_BB_MIN=0.05 | IA2: WT_15M_BOUNCE_BB_MIN=0.1 | IB2: WT_15M_BOUNCE_BB_MIN=0.2 | IC2: WT_15M_BOUNCE_HIGH_1H_GT_PREV=True | ID2: WT_15M_BOUNCE_HIGH_1H_GT_PREV=False | IE2: WT_15M_BOUNCE_LOW_1H_GT_PREV=True | IF2: WT_15M_BOUNCE_LOW_1H_GT_PREV=False | IG2: WT_15M_BOUNCE_REL_VOL_GT_1=True | IH2: WT_15M_BOUNCE_REL_VOL_GT_1=False | II2: Live Location | IJ2: Vec Hook | IK2: Type | IL2: Correct Options
A3: DC_BREAKOUT_TF | B3: OFF | E3: -13.3501 | F3: 2.5853 | G3: =IFERROR(VLOOKUP($A3,Results_30d_Deltas!$A$2:$H$5000,7,FALSE)-E3,"") | H3: =IFERROR(VLOOKUP($A3,Results_30d_Deltas!$A$2:$H$5000,6,FALSE),"") | K3: =IF(B3=C3,"YES","NO") | AP3: 0.8725 | AQ3: 0.4886 | AR3: 0.4347 | IJ3: ez_manage.py:3078 top() | IK3: v12_quick_engine.py:1518 x5
A4: DC_BREAKOUT_TF | B4: D | E4: -13.3501 | F4: 2.5853 | G4: =IFERROR(VLOOKUP($A4,Results_30d_Deltas!$A$2:$H$5000,7,FALSE)-E3,"") | H4: =IFERROR(VLOOKUP($A4,Results_30d_Deltas!$A$2:$H$5000,6,FALSE),"") | K4: =IF(B4=C4,"YES","NO") | AP4: 0.8725 | AQ4: 0.4886 | AR4: 0.4347 | IJ4: ez_manage.py:3078 top() | IK4: v12_quick_engine.py:1518 x5
A5: DC_BREAKOUT_TF | B5: 4h | E5: -13.3501 | F5: 2.5853 | G5: =IFERROR(VLOOKUP($A5,Results_30d_Deltas!$A$2:$H$5000,7,FALSE)-E4,"") | H5: =IFERROR(VLOOKUP($A5,Results_30d_Deltas!$A$2:$H$5000,6,FALSE),"") | K5: =IF(B5=C5,"YES","NO") | AP5: 0.8725 | AQ5: 0.4886 | AR5: 0.4347 | IJ5: ez_manage.py:3078 top() | IK5: v12_quick_engine.py:1518 x5
A6: DC_BREAKOUT_TF | B6: 1h | E6: -13.3501 | F6: 2.5853 | G6: =IFERROR(VLOOKUP($A6,Results_30d_Deltas!$A$2:$H$5000,7,FALSE)-E5,"") | H6: =IFERROR(VLOOKUP($A6,Results_30d_Deltas!$A$2:$H$5000,6,FALSE),"") | K6: =IF(B6=C6,"YES","NO") | AP6: 0.8725 | AQ6: 0.4886 | AR6: 0.4347 | IJ6: ez_manage.py:3078 top() | IK6: v12_quick_engine.py:1518 x5
A7: DC_BREAKOUT_TF | B7: 15m | E7: -13.3501 | F7: 2.5853 | G7: =IFERROR(VLOOKUP($A7,Results_30d_Deltas!$A$2:$H$5000,7,FALSE)-E6,"") | H7: =IFERROR(VLOOKUP($A7,Results_30d_Deltas!$A$2:$H$5000,6,FALSE),"") | K7: =IF(B7=C7,"YES","NO") | AP7: 0.8725 | AQ7: 0.4886 | AR7: 0.4347 | IJ7: ez_manage.py:3078 top() | IK7: v12_quick_engine.py:1518 x5
A8: DC_BREAKOUT_SCORE | B8: 10 | E8: -12.2254 | F8: 3.7101 | G8: =IFERROR(VLOOKUP($A8,Results_30d_Deltas!$A$2:$H$5000,7,FALSE)-E7,"") | H8: =IFERROR(VLOOKUP($A8,Results_30d_Deltas!$A$2:$H$5000,6,FALSE),"") | K8: =IF(B8=C8,"YES","NO") | AP8: 0.4886 | AQ8: 0.8725 | AR8: 2.4718 | IJ8: ez_manage.py:3077 top() | IK8: v12_quick_engine.py:1517 x18
A9: DC_BREAKOUT_SCORE | B9: 15 | E9: -12.2254 | F9: 3.7101 | G9: =IFERROR(VLOOKUP($A9,Results_30d_Deltas!$A$2:$H$5000,7,FALSE)-E8,"") | H9: =IFERROR(VLOOKUP($A9,Results_30d_Deltas!$A$2:$H$5000,6,FALSE),"") | K9: =IF(B9=C9,"YES","NO") | AP9: 0.4886 | AQ9: 0.8725 | AR9: 2.4718 | IJ9: ez_manage.py:3077 top() | IK9: v12_quick_engine.py:1517 x18
A10: DC_BREAKOUT_SCORE | B10: 20 | E10: -12.2254 | F10: 3.7101 | G10: =IFERROR(VLOOKUP($A10,Results_30d_Deltas!$A$2:$H$5000,7,FALSE)-E9,"") | H10: =IFERROR(VLOOKUP($A10,Results_30d_Deltas!$A$2:$H$5000,6,FALSE),"") | K10: =IF(B10=C10,"YES","NO") | AP10: 0.4886 | AQ10: 0.8725 | AR10: 2.4718 | IJ10: ez_manage.py:3077 top() | IK10: v12_quick_engine.py:1517 x18
A11: DC_BREAKOUT_SCORE | B11: 25 | E11: -12.2254 | F11: 3.7101 | G11: =IFERROR(VLOOKUP($A11,Results_30d_Deltas!$A$2:$H$5000,7,FALSE)-E10,"") | H11: =IFERROR(VLOOKUP($A11,Results_30d_Deltas!$A$2:$H$5000,6,FALSE),"") | K11: =IF(B11=C11,"YES","NO") | AP11: 0.4886 | AQ11: 0.8725 | AR11: 2.4718 | IJ11: ez_manage.py:3077 top() | IK11: v12_quick_engine.py:1517 x18
A12: DC_BREAKOUT_SCORE | B12: 30 | E12: -12.2254 | F12: 3.7101 | G12: =IFERROR(VLOOKUP($A12,Results_30d_Deltas!$A$2:$H$5000,7,FALSE)-E11,"") | H12: =IFERROR(VLOOKUP($A12,Results_30d_Deltas!$A$2:$H$5000,6,FALSE),"") | K12: =IF(B12=C12,"YES","NO") | AP12: 0.4886 | AQ12: 0.8725 | AR12: 2.4718 | IJ12: ez_manage.py:3077 top() | IK12: v12_quick_engine.py:1517 x18
A13: BB_BREAKOUT_SCORE | B13: 10 | E13: -13.3501 | F13: 2.5853 | G13: =IFERROR(VLOOKUP($A13,Results_30d_Deltas!$A$2:$H$5000,7,FALSE)-E12,"") | H13: =IFERROR(VLOOKUP($A13,Results_30d_Deltas!$A$2:$H$5000,6,FALSE),"") | K13: =IF(B13=C13,"YES","NO") | AP13: 0.8638 | AQ13: 0 | AR13: 2.5853 | IJ13: ez_manage.py:2963 top() | IK13: v12_quick_engine.py:1255 x6
A14: BB_BREAKOUT_SCORE | B14: 15 | E14: -13.3501 | F14: 2.5853 | G14: =IFERROR(VLOOKUP($A14,Results_30d_Deltas!$A$2:$H$5000,7,FALSE)-E13,"") | H14: =IFERROR(VLOOKUP($A14,Results_30d_Deltas!$A$2:$H$5000,6,FALSE),"") | K14: =IF(B14=C14,"YES","NO") | AP14: 0.8638 | AQ14: 0 | AR14: 2.5853 | IJ14: ez_manage.py:2963 top() | IK14: v12_quick_engine.py:1255 x6
A15: BB_BREAKOUT_SCORE | B15: 20 | E15: -13.3501 | F15: 2.5853 | G15: =IFERROR(VLOOKUP($A15,Results_30d_Deltas!$A$2:$H$5000,7,FALSE)-E14,"") | H15: =IFERROR(VLOOKUP($A15,Results_30d_Deltas!$A$2:$H$5000,6,FALSE),"") | K15: =IF(B15=C15,"YES","NO") | AP15: 0.8638 | AQ15: 0 | AR15: 2.5853 | IJ15: ez_manage.py:2963 top() | IK15: v12_quick_engine.py:1255 x6
... A23: RZ_BREAKOUT_ENTRY_ENABLED | B23: True | E23: -13.3501 | F23: 2.5853 | G23: =IFERROR(VLOOKUP($A23,Results_30d_Deltas!$A$2:$H$5000,7,FALSE)-E22,"") | H23: =IFERROR(VLOOKUP($A23,Results_30d_Deltas!$A$2:$H$5000,6,FALSE),"") | K23: =IF(B23=C23,"YES","NO") | AP23: 0.8638 | AQ23: 0.4347 | AR23: 0 | IJ23: ez_manage.py:5398 top() | IK23: v12_quick_engine.py:3021 x3
A24: ATR_ADAPTIVE_SIZING_TARGET_PCT | B24: 1.0 | E24: -13.3501 | F24: 2.5853 | G24: =IFERROR(VLOOKUP($A24,Results_30d_Deltas!$A$2:$H$5000,7,FALSE)-E23,"") | H24: =IFERROR(VLOOKUP($A24,Results_30d_Deltas!$A$2:$H$5000,6,FALSE),"") | K24: =IF(B24=C24,"YES","NO") | IJ24: ez_manage.py:4327 top() | IK24: v12_quick_engine.py:1209 x7
A25: ATR_ADAPTIVE_SIZING_TARGET_PCT | B25: 1.5 | E25: -13.3501 | F25: 2.5853 | G25: =IFERROR(VLOOKUP($A25,Results_30d_Deltas!$A$2:$H$5000,7,FALSE)-E24,"") | H25: =IFERROR(VLOOKUP($A25,Results_30d_Deltas!$A$2:$H$5000,6,FALSE),"") | K25: =IF(B25=C25,"YES","NO") | IJ25: ez_manage.py:4327 top() | IK25: v12_quick_engine.py:1209 x7
A26: ATR_ADAPTIVE_SIZING_TARGET_PCT | B26: 2.0 | E26: -13.3501 | F26: 2.5853 | G26: =IFERROR(VLOOKUP($A26,Results_30d_Deltas!$A$2:$H$5000,7,FALSE)-E25,"") | H26: =IFERROR(VLOOKUP($A26,Results_30d_Deltas!$A$2:$H$5000,6,FALSE),"") | K26: =IF(B26=C26,"YES","NO") | IJ26: ez_manage.py:4327 top() | IK26: v12_quick_engine.py:1209 x7
A27: ATR_ADAPTIVE_SIZING_TARGET_PCT | B27: 2.5 | E27: -13.3501 | F27: 2.5853 | G27: =IFERROR(VLOOKUP($A27,Results_30d_Deltas!$A$2:$H$5000,7,FALSE)-E26,"") | H27: =IFERROR(VLOOKUP($A27,Results_30d_Deltas!$A$2:$H$5000,6,FALSE),"") | K27: =IF(B27=C27,"YES","NO") | IJ27: ez_manage.py:4327 top() | IK27: v12_quick_engine.py:1209 x7
A28: ATR_ADAPTIVE_SIZING_TARGET_PCT | B28: 3.0 | E28: -13.3501 | F28: 2.5853 | G28: =IFERROR(VLOOKUP($A28,Results_30d_Deltas!$A$2:$H$5000,7,FALSE)-E27,"") | H28: =IFERROR(VLOOKUP($A28,Results_30d_Deltas!$A$2:$H$5000,6,FALSE),"") | K28: =IF(B28=C28,"YES","NO") | IJ28: ez_manage.py:4327 top() | IK28: v12_quick_engine.py:1209 x7
A29: ATR_ADAPTIVE_STOP_MULT | B29: 1.0 | E29: -13.3501 | F29: 2.5853 | G29: =IFERROR(VLOOKUP($A29,Results_30d_Deltas!$A$2:$H$5000,7,FALSE)-E28,"") | H29: =IFERROR(VLOOKUP($A29,Results_30d_Deltas!$A$2:$H$5000,6,FALSE),"") | K29: =IF(B29=C29,"YES","NO") | IJ29: ez_manage.py:4329 top() | IK29: v12_quick_engine.py:1211 x6
A30: ATR_ADAPTIVE_STOP_MULT | B30: 1.5 | E30: -13.3501 | F30: 2.5853 | G30: =IFERROR(VLOOKUP($A30,Results_30d_Deltas!$A$2:$H$5000,7,FALSE)-E29,"") | H30: =IFERROR(VLOOKUP($A30,Results_30d_Deltas!$A$2:$H$5000,6,FALSE),"") | K30: =IF(B30=C30,"YES","NO") | IJ30: ez_manage.py:4329 top() | IK30: v12_quick_engine.py:1211 x6
A31: ATR_ADAPTIVE_STOP_MULT | B31: 2.0 | E31: -13.3501 | F31: 2.5853 | G31: =IFERROR(VLOOKUP($A31,Results_30d_Deltas!$A$2:$H$5000,7,FALSE)-E30,"") | H31: =IFERROR(VLOOKUP($A31,Results_30d_Deltas!$A$2:$H$5000,6,FALSE),"") | K31: =IF(B31=C31,"YES","NO") | IJ31: ez_manage.py:4329 top() | IK31: v12_quick_engine.py:1211 x6
A32: ATR_ADAPTIVE_STOP_MULT | B32: 2.5 | E32: -13.3501 | F32: 2.5853 | G32: =IFERROR(VLOOKUP($A32,Results_30d_Deltas!$A$2:$H$5000,7,FALSE)-E31,"") | H32: =IFERROR(VLOOKUP($A32,Results_30d_Deltas!$A$2:$H$5000,6,FALSE),"") | K32: =IF(B32=C32,"YES","NO") | IJ32: ez_manage.py:4329 top() | IK32: v12_quick_engine.py:1211 x6
A33: ATR_ADAPTIVE_STOP_MULT | B33: 3.0 | E33: -13.3501 | F33: 2.5853 | G33: =IFERROR(VLOOKUP($A33,Results_30d_Deltas!$A$2:$H$5000,7,FALSE)-E32,"") | H33: =IFERROR(VLOOKUP($A33,Results_30d_Deltas!$A$2:$H$5000,6,FALSE),"") | K33: =IF(B33=C33,"YES","NO") | IJ33: ez_manage.py:4329 top() | IK33: v12_quick_engine.py:1211 x6
A34: ATR_LONG_WINDOW | B34: 50 | E34: -12.2254 | F34: 3.7101 | G34: =IFERROR(VLOOKUP($A34,Results_30d_Deltas!$A$2:$H$5000,7,FALSE)-E33,"") | H34: =IFERROR(VLOOKUP($A34,Results_30d_Deltas!$A$2:$H$5000,6,FALSE),"") | K34: =IF(B34=C34,"YES","NO") | IJ34: ez_manage.py:4330 top() | IK34: v12_quick_engine.py:199 x5
A35: ATR_LONG_WINDOW | B35: 75 | E35: -12.2254 | F35: 3.7101 | G35: =IFERROR(VLOOKUP($A35,Results_30d_Deltas!$A$2:$H$5000,7,FALSE)-E34,"") | H35: =IFERROR(VLOOKUP($A35,Results_30d_Deltas!$A$2:$H$5000,6,FALSE),"") | K35: =IF(B35=C35,"YES","NO") | IJ35: ez_manage.py:4330 top() | IK35: v12_quick_engine.py:199 x5
... A85: MACD_ZERO_CROSS_TF | B85: 15m | E85: -14.3964 | F85: 1.539 | G85: =IFERROR(VLOOKUP($A85,Results_30d_Deltas!$A$2:$H$5000,7,FALSE)-E84,"") | H85: =IFERROR(VLOOKUP($A85,Results_30d_Deltas!$A$2:$H$5000,6,FALSE),"") | K85: =IF(B85=C85,"YES","NO") | IJ85: ez_manage.py:3501 top() | IK85: v12_quick_engine.py:2236 x2
A86: MI_MIN_GAIN_EXIT | B86: 0 | E86: -12.2254 | F86: 3.7101 | G86: =IFERROR(VLOOKUP($A86,Results_30d_Deltas!$A$2:$H$5000,7,FALSE)-E85,"") | H86: =IFERROR(VLOOKUP($A86,Results_30d_Deltas!$A$2:$H$5000,6,FALSE),"") | K86: =IF(B86=C86,"YES","NO") | AK86: 0.8638 | AL86: 0.436 | AM86: 3.7101 | IJ86: ez_manage.py:3565 top() | IK86: v12_quick_engine.py:2342 x8
A87: MI_MIN_GAIN_EXIT | B87: 0.5 | E87: -12.2254 | F87: 3.7101 | G87: =IFERROR(VLOOKUP($A87,Results_30d_Deltas!$A$2:$H$5000,7,FALSE)-E86,"") | H87: =IFERROR(VLOOKUP($A87,Results_30d_Deltas!$A$2:$H$5000,6,FALSE),"") | K87: =IF(B87=C87,"YES","NO") | AK87: 0.8638 | AL87: 0.436 | AM87: 3.7101 | IJ87: ez_manage.py:3565 top() | IK87: v12_quick_engine.py:2342 x8
A88: MI_MIN_GAIN_EXIT | B88: 1.0 | E88: -12.2254 | F88: 3.7101 | G88: =IFERROR(VLOOKUP($A88,Results_30d_Deltas!$A$2:$H$5000,7,FALSE)-E87,"") | H88: =IFERROR(VLOOKUP($A88,Results_30d_Deltas!$A$2:$H$5000,6,FALSE),"") | K88: =IF(B88=C88,"YES","NO") | AK88: 0.8638 | AL88: 0.436 | AM88: 3.7101 | IJ88: ez_manage.py:3565 top() | IK88: v12_quick_engine.py:2342 x8
A89: MI_MIN_GAIN_EXIT | B89: 2.0 | E89: -12.2254 | F89: 3.7101 | G89: =IFERROR(VLOOKUP($A89,Results_30d_Deltas!$A$2:$H$5000,7,FALSE)-E88,"") | H89: =IFERROR(VLOOKUP($A89,Results_30d_Deltas!$A$2:$H$5000,6,FALSE),"") | K89: =IF(B89=C89,"YES","NO") | AK89: 0.8638 | AL89: 0.436 | AM89: 3.7101 | IJ89: ez_manage.py:3565 top() | IK89: v12_quick_engine.py:2342 x8
A90: PARTIAL_EXIT_FRAC | B90: 0 | E90: -12.2254 | F90: 3.7101 | G90: =IFERROR(VLOOKUP($A90,Results_30d_Deltas!$A$2:$H$5000,7,FALSE)-E89,"") | H90: =IFERROR(VLOOKUP($A90,Results_30d_Deltas!$A$2:$H$5000,6,FALSE),"") | K90: =IF(B90=C90,"YES","NO") | IJ90: ez_manage.py:6038 top() | IK90: v12_quick_engine.py:4280 x2
A91: PARTIAL_EXIT_FRAC | B91: 0.5 | E91: -12.2254 | F91: 3.7101 | G91: =IFERROR(VLOOKUP($A91,Results_30d_Deltas!$A$2:$H$5000,7,FALSE)-E90,"") | H91: =IFERROR(VLOOKUP($A91,Results_30d_Deltas!$A$2:$H$5000,6,FALSE),"") | K91: =IF(B91=C91,"YES","NO") | IJ91: ez_manage.py:6038 top() | IK91: v12_quick_engine.py:4280 x2
A92: PARTIAL_EXIT_FRAC | B92: 1.0 | E92: -12.2254 | F92: 3.7101 | G92: =IFERROR(VLOOKUP($A92,Results_30d_Deltas!$A$2:$H$5000,7,FALSE)-E91,"") | H92: =IFERROR(VLOOKUP($A92,Results_30d_Deltas!$A$2:$H$5000,6,FALSE),"") | K92: =IF(B92=C92,"YES","NO") | IJ92: ez_manage.py:6038 top() | IK92: v12_quick_engine.py:4280 x2
A93: PARTIAL_EXIT_FRAC | B93: 2.0 | E93: -12.2254 | F93: 3.7101 | G93: =IFERROR(VLOOKUP($A93,Results_30d_Deltas!$A$2:$H$5000,7,FALSE)-E92,"") | H93: =IFERROR(VLOOKUP($A93,Results_30d_Deltas!$A$2:$H$5000,6,FALSE),"") | K93: =IF(B93=C93,"YES","NO") | IJ93: ez_manage.py:6038 top() | IK93: v12_quick_engine.py:4280 x2
A94: QUICK_REENTRY_60MIN_MIN_PCT | B94: 0 | E94: -12.2254 | F94: 3.7101 | G94: =IFERROR(VLOOKUP($A94,Results_30d_Deltas!$A$2:$H$5000,7,FALSE)-E93,"") | H94: =IFERROR(VLOOKUP($A94,Results_30d_Deltas!$A$2:$H$5000,6,FALSE),"") | K94: =IF(B94=C94,"YES","NO") | IJ94: ez_manage.py:6042 top() | IK94: v12_quick_engine.py:4283 x4
A95: QUICK_REENTRY_60MIN_MIN_PCT | B95: 0.5 | E95: -12.2254 | F95: 3.7101 | G95: =IFERROR(VLOOKUP($A95,Results_30d_Deltas!$A$2:$H$5000,7,FALSE)-E94,"") | H95: =IFERROR(VLOOKUP($A95,Results_30d_Deltas!$A$2:$H$5000,6,FALSE),"") | K95: =IF(B95=C95,"YES","NO") | IJ95: ez_manage.py:6042 top() | IK95: v12_quick_engine.py:4283 x4
A96: QUICK_REENTRY_60MIN_MIN_PCT | B96: 1.0 | E96: -12.2254 | F96: 3.7101 | G96: =IFERROR(VLOOKUP($A96,Results_30d_Deltas!$A$2:$H$5000,7,FALSE)-E95,"") | H96: =IFERROR(VLOOKUP($A96,Results_30d_Deltas!$A$2:$H$5000,6,FALSE),"") | K96: =IF(B96=C96,"YES","NO") | IJ96: ez_manage.py:6042 top() | IK96: v12_quick_engine.py:4283 x4
...

Sheet ENTRY_CONFIRMATION_GATES
A1: 03 ENTRY_CONFIRMATION_GATES - 4 bases -> 11 rows - 231 per-row FULLY CONNECTED
