Workbook

Sheet INSTRUCTIONS
A1: TEMPLATE_30d_matrix -- CRYSTAL CLEAR INSTRUCTIONS (2026-09-11) -- ANY DUMB AGENT CAN EXECUTE *** ON S1 NEVER ON MACBOOK *** If you are reading this, YOU MUST FOLLOW EVERY LINE. No skipping, no guessing, no inventing numbers. This tab + FILTER_DICTIONARY_V2 + v14_sequential_filler.py + v12_quick_engine/backtest_v12_engine are LAW.
A2: ⚠️ MACHINE RULE -- MAC ONLY TRADES LIVE (ez_manage / tradier_manage) AND NEVER TESTS. MAC has 5 NPZs and NO NVDA.npz / NO CRWD.npz → any S1 vector returns 'no NPZ' in 0.2s. S1 = 157.180.125.52 (s1-int via gateway 157.90.168.35) has 1000+ NPZs (42-49M) and is ONLY test host (S2 for mega sweeps only). If on MacBook, SSH FIRST: ssh 157.180.125.52 OR ssh -fNT s1-sftp && ssh s1-int. Verify: ls /home/niels/binance-sandbox/backtest_v8/indicators/NVDA.npz must exist. If not, STOP.
A3: ⚠️ SYNC & BACKUP RULE -- KEEP ALL FIXES synced Mac <-> S1 via rsync -avz -e 'ssh -p 2201' and KEEP BACKUPS before EVERY edit: cp <file> backups/before_<desc>_$(date +%Y%m%d%H%M).py . Autosave launchd commits git every 15min. /backups/ ONLY reliable history. After BACKTEST_BIBLE.md edit run tools/sync_backtest_bible.sh (SHA256). NEVER edit S1 copy directly without rsync back.
A4: ⚠️ INSTRUCTIONS ARE LAW -- v12_pilot.py, v12_pilot_sheet_runner.py, v14_sequential_filler.py, ANY agent MUST READ THIS TAB AT STARTUP and FOLLOW IT. This tab wins over code if conflict after 2026-09-11. Also read BACKTEST_BIBLE.md, QuickConfig (v12_quick_engine:5893 1118 fields, 851 causal), and FILTER_DICTIONARY_V2 (426 rows).
A5: 0) PRECONDITION -- DO NOT START UNTIL DEFAULTS ARE BOLD. Every row where B == live default (config.py Config for crypto / config_tradier.py TradierConfig for stocks = 1118 fields) must have A and B bold. ~50% rows bold. NEVER edit B (candidate value in col B). You only write C (override), E (baseline gain), F (delta vs E), G (variant gain), and L:BI per-filter deltas.
A6: 1) CREATE BASELINE WITH per_sym OVERRIDES for EXACT sym_side. GET OVERRIDES = union of data/hourly_reconfig/trb/active_config.json AND data/hourly_reconfig/per_sym_active_config.json for YOUR EXACT SYM_SIDE (SYMBOL+_LONG vs _SHORT are DIFFERENT, NEVER reuse). Example NVDA_LONG 8 overrides (BOUNCE_AUGMENT...), CRWD_SHORT 0. For each switch in union, find row where A==switch name and write override into C, BOLD GREEN font 006100 on fill C6EFCE. Do ALL overrides BEFORE baseline calc. Then baseline = vector_evaluate(sym_side, overrides) AND live_evaluate(sym_side, overrides) — they must parity (trades 0.80..1.25, gain 0.5pp|15%, sharpe 0.25). Write TEMPLATE_BASELINE_METRICS!B2 = gain, B? = bh. Verify WT_15M_BOUNCE True adds >100 trades/mo (fix in v12_quick_engine:5894 MAX_BARS_AGO=100). If trades 0 or <30, STOP and spawn agent to fix v12_quick_engine (6817/9010).
A7: 1b) BASELINE E2 = TEMPLATE_BASELINE_METRICS!B2 (gain). E3 = IF(F3>0,E2+F3,"") chain. Never repeat E. First pilot: WT_15M_BOUNCE True must be first positive delta or calculation BROKEN.
A8: 2) FOR EVERY ROW (EVERY SWITCH) TEST EVERY APPLICABLE FILTER × EVERY SETTING. MANDATORY until >100 sym_sides tested (see rule 9). Applicable = FILTER_DICTIONARY_V2 row where (sheets_app contains this tab lifecycle ENTRY/EXIT/REENTRY/AUGMENT/REDUCE or GLOBAL_CHECK) AND (gates token overlap with this switch OR rec is GENERAL). Use get_opportune_filters(switch, sheet) — it already implements this. For WT_15M_BOUNCE_OPEN_ENABLED True you MUST test its 12 sub-filters (BB_MIN 0.05/0.1/0.2, BB_MAX 0.95/0.9/0.8, LOW_1H True/False, HIGH_1H True/False, REL_VOL True/False) even if WT alone delta is NEG — they are FILTERS in FILTER_DICTIONARY, not switches. Do NOT discard. COL J lists per-switch opportune filters (up to 6 shown), COL L:BI holds per-filter deltas (one column per filter=opt).
A9: 2a) EVALUATION: For this row, build candidates: [switch alone] + [switch+each single filter distinct opt (skip opt==cur)] . If best single delta <=0, also test ALL combos of 2 and 3 among top-8 singles (C8,2=28 + C8,3=56 =84 combos). Each candidate = sanitize_overrides(variant, defaults) then vector_evaluate via prepare_batch/evaluate_prepared_sanitized (70-136ms, million/hour). NEVER use per-cell load_npz (3.65s) — use prepare_batch once per sym_side. Log every candidate: [CANDIDATE] switch=cand[+filter=opt] vec_gain delta vs cum trades sharpe. Pick MAX delta (beating-ideas-to-death, not first positive).
A10: 2b) DUPLICATE/0.0 CHECK — Immediately flag DUPLICATE (same delta for 2 different switches → formula bug, e.g. shared adx gate) or 0.0 (dead switch or >5s VECTOR_STALL). If duplicate/0.0, revise v12_quick_engine wiring to exact live numpy (622 not-causal) and run live_evaluate for parity. Fix before promoting.
A11: 2c) PROGRESS REPORT every 5min: count filled F cells per sheet (e.g. NVDA 2790/2823=98.8% — one baseline empty per sheet expected). Write data/reports/lifecycle_pilot/*_pilot_progress.json and SPREADSHEETS/*_pilot_progress.html refreshed 60s. Also log [ROW] sheet!r switch=cand[+filter] delta vs cum -> NEG/POSITIVE candidate.
A12: 3) PROMOTION: Only if best delta >0 AND live_evaluate parity passes (trades 0.80..1.25, gain 0.5pp|15%, sharpe 0.25) AND (vector_only deferred → final cumulative live check). Then write C = cand (bold green 006100 on C6EFCE), cumulative_gain = vec_gain, cumulative_overrides[switch]=cand and if filter best exists also [filter]=fval. Write Results_30d_Deltas row: key=switch=cand, col5=delta, col6=variant_gain, col8=variant_gain, col10=trades, col11=max_dd, col12=tim. Also batch write L:BI deltas for this row (one col per filter=opt = delta). E for this row = IF(F>0,Eprev+F,Eprev) — only F>0 gets bold green E/F/G and C. F/G written even if <=0 for audit, but E stays empty.
... A23: 14) FINAL CHECK -- Before declaring done, verify: (a) every row has F via Results key=switch=cand VLOOKUP $A&"="&$B, (b) L:BI columns exist for every applicable filter (R-W, 40 col cap), (c) Results_30d_Deltas has delta, gain, trades, sharpe for every pos, (d) filename bh/gain correct, (e) v14 where applicable, (f) >100 sym_sides threshold respected, (g) colors green/blue/darker per provenance.

Sheet INSTRUCTIONS_V2
A1: TEMPLATE_V2_IDEA_GROUPED 231 per-row FULLY CONNECTED 2026-09-08 - every numpy identical to live
A2: Retraced from early today 231 L:IH (TEMPLATE.xlsx 1.7M) - Sep 5 114 per-row was synthetic/disconnected. This file keeps 231 per-row L:IH (every filter TF OFF/D/4h/1h/15m wired).
A3: 01. ENTRY_REVERSAL_BOUNCE - 8 bases -> 21 rows - 231 per-row
A4: 02. ENTRY_BREAKOUT_CHANNEL - 54 bases -> 210 rows - 231 per-row
A5: 03. ENTRY_CONFIRMATION_GATES - 4 bases -> 11 rows - 231 per-row
A6: 04. EXIT_STRUCTURAL - 2 bases -> 6 rows - 231 per-row
A7: 05. EXIT_VELOCITY - 26 bases -> 80 rows - 231 per-row
A8: 06. REENTRY_WINDOWED - 68 bases -> 249 rows - 231 per-row
A9: 07. REENTRY_ADAPTIVE - 10 bases -> 38 rows - 231 per-row
A10: 08. AUGMENT_TREND - 5 bases -> 24 rows - 231 per-row
A11: 09. AUGMENT_RISK_SIZING - 17 bases -> 56 rows - 231 per-row
A12: 10. REDUCE_PROFIT_LOCK - 19 bases -> 53 rows - 231 per-row
... A15: 2026-09-11 UPDATE: See INSTRUCTIONS tab rows 9,12,14 for >100 sym_sides threshold, blanket at end of each tab, and green/blue/darker proven colors. v14 implements get_opportune_filters + 84 combos + blanket GENERAL. ALL filters until 100, then useful per universe.

Sheet ENTRY_REVERSAL_BOUNCE
A1: 01 ENTRY_REVERSAL_BOUNCE - 8 bases -> 21 rows - 231 per-row FULLY CONNECTED
A2: Switch | B2: default | C2: override | D2: Family | E2: BASELINE | F2: VECTOR_DELTA | G2: LIVE_DELTA | H2: LIVE_SHARPE | I2: REAL_COMPLETE | J2: PER_ROW_FILTERS | K2: is_default (backup if bold lost) | L2: ATR_TRAIL_FILTER_TF=OFF | M2: ATR_TRAIL_FILTER_TF=D | N2: ATR_TRAIL_FILTER_TF=4h | O2: ATR_TRAIL_FILTER_TF=1h | P2: ATR_TRAIL_FILTER_TF=15m | Q2: BAR_PATTERNS_FILTER_TF=OFF | R2: BAR_PATTERNS_FILTER_TF=D | S2: BAR_PATTERNS_FILTER_TF=4h | T2: BAR_PATTERNS_FILTER_TF=1h | U2: BAR_PATTERNS_FILTER_TF=15m | V2: BB_PULLBACK_GATE_FILTER_TF=OFF | W2: BB_PULLBACK_GATE_FILTER_TF=D | X2: BB_PULLBACK_GATE_FILTER_TF=4h | Y2: BB_PULLBACK_GATE_FILTER_TF=1h | Z2: BB_PULLBACK_GATE_FILTER_TF=15m | AA2: BB_RECOVERY_ENTRY_FILTER_TF=OFF | AB2: BB_RECOVERY_ENTRY_FILTER_TF=D | AC2: BB_RECOVERY_ENTRY_FILTER_TF=4h | AD2: BB_RECOVERY_ENTRY_FILTER_TF=1h | AE2: BB_RECOVERY_ENTRY_FILTER_TF=15m | AF2: BB_RECOVERY_FILTER_TF=OFF | AG2: BB_RECOVERY_FILTER_TF=D | AH2: BB_RECOVERY_FILTER_TF=4h | AI2: BB_RECOVERY_FILTER_TF=1h | AJ2: BB_RECOVERY_FILTER_TF=15m | AK2: BREAKEVEN_GAIN_EROSION_FILTER_TF=OFF | AL2: BREAKEVEN_GAIN_EROSION_FILTER_TF=D | AM2: BREAKEVEN_GAIN_EROSION_FILTER_TF=4h | AN2: BREAKEVEN_GAIN_EROSION_FILTER_TF=1h | AO2: BREAKEVEN_GAIN_EROSION_FILTER_TF=15m | AP2: BREAKOUT_RETEST_FILTER_TF=OFF | AQ2: BREAKOUT_RETEST_FILTER_TF=D | AR2: BREAKOUT_RETEST_FILTER_TF=4h | AS2: BREAKOUT_RETEST_FILTER_TF=1h | AT2: BREAKOUT_RETEST_FILTER_TF=15m | AU2: BT_WT_CROSS_LADDER_FILTER_TF=OFF | AV2: BT_WT_CROSS_LADDER_FILTER_TF=D | AW2: BT_WT_CROSS_LADDER_FILTER_TF=4h | AX2: BT_WT_CROSS_LADDER_FILTER_TF=1h | AY2: BT_WT_CROSS_LADDER_FILTER_TF=15m | AZ2: CANDLE_PATTERN_STOPS_FILTER_TF=OFF | BA2: CANDLE_PATTERN_STOPS_FILTER_TF=D | BB2: CANDLE_PATTERN_STOPS_FILTER_TF=4h | BC2: CANDLE_PATTERN_STOPS_FILTER_TF=1h | BD2: CANDLE_PATTERN_STOPS_FILTER_TF=15m | BE2: CIRCUIT_SHARPE_GATES_FILTER_TF=OFF | BF2: CIRCUIT_SHARPE_GATES_FILTER_TF=D | BG2: CIRCUIT_SHARPE_GATES_FILTER_TF=4h | BH2: CIRCUIT_SHARPE_GATES_FILTER_TF=1h | BI2: CIRCUIT_SHARPE_GATES_FILTER_TF=15m | BJ2: DC_BREACH_REDUCE_FILTER_TF=OFF | BK2: DC_BREACH_REDUCE_FILTER_TF=D | BL2: DC_BREACH_REDUCE_FILTER_TF=4h | BM2: DC_BREACH_REDUCE_FILTER_TF=1h | BN2: DC_BREACH_REDUCE_FILTER_TF=15m | BO2: DC_BREAK_FILTER_TF=OFF | BP2: DC_BREAK_FILTER_TF=D | BQ2: DC_BREAK_FILTER_TF=4h | BR2: DC_BREAK_FILTER_TF=1h | BS2: DC_BREAK_FILTER_TF=15m | BT2: DC_MOMENTUM_BOTA_SCORER_FILTER_TF=OFF | BU2: DC_MOMENTUM_BOTA_SCORER_FILTER_TF=D | BV2: DC_MOMENTUM_BOTA_SCORER_FILTER_TF=4h | BW2: DC_MOMENTUM_BOTA_SCORER_FILTER_TF=1h | BX2: DC_MOMENTUM_BOTA_SCORER_FILTER_TF=15m | BY2: DELTA_ENGINE_FILTER_TF=OFF | BZ2: DELTA_ENGINE_FILTER_TF=D | CA2: DELTA_ENGINE_FILTER_TF=4h | CB2: DELTA_ENGINE_FILTER_TF=1h | CC2: DELTA_ENGINE_FILTER_TF=15m | CD2: EMA_9_21_FILTER_FILTER_TF=OFF | CE2: EMA_9_21_FILTER_FILTER_TF=D | CF2: EMA_9_21_FILTER_FILTER_TF=4h | CG2: EMA_9_21_FILTER_FILTER_TF=1h | CH2: EMA_9_21_FILTER_FILTER_TF=15m | CI2: EMA_BLANKET_FILTER_FILTER_TF=OFF | CJ2: EMA_BLANKET_FILTER_FILTER_TF=D | CK2: EMA_BLANKET_FILTER_FILTER_TF=4h | CL2: EMA_BLANKET_FILTER_FILTER_TF=1h | CM2: EMA_BLANKET_FILTER_FILTER_TF=15m | CN2: EMERGENCY_BRAKE_FILTER_TF=OFF | CO2: EMERGENCY_BRAKE_FILTER_TF=D | CP2: EMERGENCY_BRAKE_FILTER_TF=4h | CQ2: EMERGENCY_BRAKE_FILTER_TF=1h | CR2: EMERGENCY_BRAKE_FILTER_TF=15m | CS2: EXIT_R1_R2_FILTER_TF=OFF | CT2: EXIT_R1_R2_FILTER_TF=D | CU2: EXIT_R1_R2_FILTER_TF=4h | CV2: EXIT_R1_R2_FILTER_TF=1h | CW2: EXIT_R1_R2_FILTER_TF=15m | CX2: EXIT_TIGHT_BREAKOUT_SCORER_FILTER_TF=OFF | CY2: EXIT_TIGHT_BREAKOUT_SCORER_FILTER_TF=D | CZ2: EXIT_TIGHT_BREAKOUT_SCORER_FILTER_TF=4h | DA2: EXIT_TIGHT_BREAKOUT_SCORER_FILTER_TF=1h | DB2: EXIT_TIGHT_BREAKOUT_SCORER_FILTER_TF=15m | DC2: EXIT_TOP_FADE_FILTER_TF=OFF | DD2: EXIT_TOP_FADE_FILTER_TF=D | DE2: EXIT_TOP_FADE_FILTER_TF=4h | DF2: EXIT_TOP_FADE_FILTER_TF=1h | DG2: EXIT_TOP_FADE_FILTER_TF=15m | DH2: EXIT_TO_REDUCE_ADAPTER_FILTER_TF=OFF | DI2: EXIT_TO_REDUCE_ADAPTER_FILTER_TF=D | DJ2: EXIT_TO_REDUCE_ADAPTER_FILTER_TF=4h | DK2: EXIT_TO_REDUCE_ADAPTER_FILTER_TF=1h | DL2: EXIT_TO_REDUCE_ADAPTER_FILTER_TF=15m | DM2: FAST_RISER_FILTER_TF=OFF | DN2: FAST_RISER_FILTER_TF=D | DO2: FAST_RISER_FILTER_TF=4h | DP2: FAST_RISER_FILTER_TF=1h | DQ2: FAST_RISER_FILTER_TF=15m | DR2: FH_MOMENTUM_FILTER_TF=OFF | DS2: FH_MOMENTUM_FILTER_TF=D | DT2: FH_MOMENTUM_FILTER_TF=4h | DU2: FH_MOMENTUM_FILTER_TF=1h | DV2: FH_MOMENTUM_FILTER_TF=15m | DW2: FIRST_OPEN_THROTTLE_FILTER_TF=OFF | DX2: FIRST_OPEN_THROTTLE_FILTER_TF=D | DY2: FIRST_OPEN_THROTTLE_FILTER_TF=4h | DZ2: FIRST_OPEN_THROTTLE_FILTER_TF=1h | EA2: FIRST_OPEN_THROTTLE_FILTER_TF=15m | EB2: FROZEN_STOP_FILTER_TF=OFF | EC2: FROZEN_STOP_FILTER_TF=D | ED2: FROZEN_STOP_FILTER_TF=4h | EE2: FROZEN_STOP_FILTER_TF=1h | EF2: FROZEN_STOP_FILTER_TF=15m | EG2: GOLDEN_RULE_ENFORCE_FILTER_TF=OFF | EH2: GOLDEN_RULE_ENFORCE_FILTER_TF=D | EI2: GOLDEN_RULE_ENFORCE_FILTER_TF=4h | EJ2: GOLDEN_RULE_ENFORCE_FILTER_TF=1h | EK2: GOLDEN_RULE_ENFORCE_FILTER_TF=15m | EL2: GOLDEN_RULE_HTF_VOTE_FILTER_TF=OFF | EM2: GOLDEN_RULE_HTF_VOTE_FILTER_TF=D | EN2: GOLDEN_RULE_HTF_VOTE_FILTER_TF=4h | EO2: GOLDEN_RULE_HTF_VOTE_FILTER_TF=1h | EP2: GOLDEN_RULE_HTF_VOTE_FILTER_TF=15m | EQ2: GR_FILTER_VEC_FILTER_TF=OFF | ER2: GR_FILTER_VEC_FILTER_TF=D | ES2: GR_FILTER_VEC_FILTER_TF=4h | ET2: GR_FILTER_VEC_FILTER_TF=1h | EU2: GR_FILTER_VEC_FILTER_TF=15m | EV2: GR_V5_STATE_FILTER_TF=OFF | EW2: GR_V5_STATE_FILTER_TF=D | EX2: GR_V5_STATE_FILTER_TF=4h | EY2: GR_V5_STATE_FILTER_TF=1h | EZ2: GR_V5_STATE_FILTER_TF=15m | FA2: HAIKU_WINNER_FILTER_TF=OFF | FB2: HAIKU_WINNER_FILTER_TF=D | FC2: HAIKU_WINNER_FILTER_TF=4h | FD2: HAIKU_WINNER_FILTER_TF=1h | FE2: HAIKU_WINNER_FILTER_TF=15m | FF2: LH_HL_FILTER_TF_REQ=2 | FG2: LH_HL_FILTER_TF_REQ=2_ALT | FH2: LIVE_ENTRY_ENGINE_FILTER_TF=OFF | FI2: LIVE_ENTRY_ENGINE_FILTER_TF=D | FJ2: LIVE_ENTRY_ENGINE_FILTER_TF=4h | FK2: LIVE_ENTRY_ENGINE_FILTER_TF=1h | FL2: LIVE_ENTRY_ENGINE_FILTER_TF=15m | FM2: LIVE_ONLY_SIGNALS_BATCH5_FILTER_TF=OFF | FN2: LIVE_ONLY_SIGNALS_BATCH5_FILTER_TF=D | FO2: LIVE_ONLY_SIGNALS_BATCH5_FILTER_TF=4h | FP2: LIVE_ONLY_SIGNALS_BATCH5_FILTER_TF=1h | FQ2: LIVE_ONLY_SIGNALS_BATCH5_FILTER_TF=15m | FR2: MANDATORY_REENTRY_WT_FILTER_TF_MODE=15m_only | FS2: MANDATORY_REENTRY_WT_FILTER_TF_MODE=15m_only_ALT | FT2: MOM3_FILTER_TF=OFF | FU2: MOM3_FILTER_TF=D | FV2: MOM3_FILTER_TF=4h | FW2: MOM3_FILTER_TF=1h | FX2: MOM3_FILTER_TF=15m | FY2: MOMENTUM_BREAKOUT_FILTER_TF=OFF | FZ2: MOMENTUM_BREAKOUT_FILTER_TF=D | GA2: MOMENTUM_BREAKOUT_FILTER_TF=4h | GB2: MOMENTUM_BREAKOUT_FILTER_TF=1h | GC2: MOMENTUM_BREAKOUT_FILTER_TF=15m | GD2: MTF_ARMED_ENTRIES_FILTER_TF=OFF | GE2: MTF_ARMED_ENTRIES_FILTER_TF=D | GF2: MTF_ARMED_ENTRIES_FILTER_TF=4h | GG2: MTF_ARMED_ENTRIES_FILTER_TF=1h | GH2: MTF_ARMED_ENTRIES_FILTER_TF=15m | GI2: MTF_ATR_TRAIL_FILTER_TF=OFF | GJ2: MTF_ATR_TRAIL_FILTER_TF=D | GK2: MTF_ATR_TRAIL_FILTER_TF=4h | GL2: MTF_ATR_TRAIL_FILTER_TF=1h | GM2: MTF_ATR_TRAIL_FILTER_TF=15m | GN2: MTF_DC_REJECT_FILTER_TF=OFF | GO2: MTF_DC_REJECT_FILTER_TF=D | GP2: MTF_DC_REJECT_FILTER_TF=4h | GQ2: MTF_DC_REJECT_FILTER_TF=1h | GR2: MTF_DC_REJECT_FILTER_TF=15m | GS2: NEWBORN_LOSS_KILL_FILTER_TF=OFF | GT2: NEWBORN_LOSS_KILL_FILTER_TF=D | GU2: NEWBORN_LOSS_KILL_FILTER_TF=4h | GV2: NEWBORN_LOSS_KILL_FILTER_TF=1h | GW2: NEWBORN_LOSS_KILL_FILTER_TF=15m | GX2: NEWBORN_PROTECT_FILTER_TF=OFF | GY2: NEWBORN_PROTECT_FILTER_TF=D | GZ2: NEWBORN_PROTECT_FILTER_TF=4h | HA2: NEWBORN_PROTECT_FILTER_TF=1h | HB2: NEWBORN_PROTECT_FILTER_TF=15m | HC2: NOLOSS_BYPASS_WT5OF5_FILTER_TF=OFF | HD2: NOLOSS_BYPASS_WT5OF5_FILTER_TF=D | HE2: NOLOSS_BYPASS_WT5OF5_FILTER_TF=4h | HF2: NOLOSS_BYPASS_WT5OF5_FILTER_TF=1h | HG2: NOLOSS_BYPASS_WT5OF5_FILTER_TF=15m | HH2: OPEN_INTENT_SIZE_GATES_FILTER_TF=OFF | HI2: OPEN_INTENT_SIZE_GATES_FILTER_TF=D | HJ2: OPEN_INTENT_SIZE_GATES_FILTER_TF=4h | HK2: OPEN_INTENT_SIZE_GATES_FILTER_TF=1h | HL2: OPEN_INTENT_SIZE_GATES_FILTER_TF=15m | HM2: PARTIAL_PROFIT_LOCK_V2_FILTER_TF=OFF | HN2: PARTIAL_PROFIT_LOCK_V2_FILTER_TF=D | HO2: PARTIAL_PROFIT_LOCK_V2_FILTER_TF=4h | HP2: PARTIAL_PROFIT_LOCK_V2_FILTER_TF=1h | HQ2: PARTIAL_PROFIT_LOCK_V2_FILTER_TF=15m | HR2: PEAK_GIVEBACK_BE_EROSION_FILTER_TF=OFF | HS2: PEAK_GIVEBACK_BE_EROSION_FILTER_TF=D | HT2: PEAK_GIVEBACK_BE_EROSION_FILTER_TF=4h | HU2: PEAK_GIVEBACK_BE_EROSION_FILTER_TF=1h | HV2: PEAK_GIVEBACK_BE_EROSION_FILTER_TF=15m | HW2: WT_15M_BOUNCE_BB_MAX=0.95 | HX2: WT_15M_BOUNCE_BB_MAX=0.9 | HY2: WT_15M_BOUNCE_BB_MAX=0.8 | HZ2: WT_15M_BOUNCE_BB_MIN=0.05 | IA2: WT_15M_BOUNCE_BB_MIN=0.1 | IB2: WT_15M_BOUNCE_BB_MIN=0.2 | IC2: WT_15M_BOUNCE_HIGH_1H_GT_PREV=True | ID2: WT_15M_BOUNCE_HIGH_1H_GT_PREV=False | IE2: WT_15M_BOUNCE_LOW_1H_GT_PREV=True | IF2: WT_15M_BOUNCE_LOW_1H_GT_PREV=False | IG2: WT_15M_BOUNCE_REL_VOL_GT_1=True | IH2: WT_15M_BOUNCE_REL_VOL_GT_1=False | II2: Live Location | IJ2: Vec Hook | IK2: Type | IL2: Correct Options
A3: WT_15M_BOUNCE_OPEN_ENABLED | B3: False | C3: WT_15M_BOUNCE_OPEN_ENABLED=False + WT_15M_BOUNCE_BB_MAX=0.8 + BB_WT_TF=15m + GR=18 + BB_RECOVERY_FILTER_TF=OFF + DC_BREAK_FILTER_TF=1h | E3: ='TEMPLATE_BASELINE_METRICS'!B2 | F3: =IFERROR(VLOOKUP($A3&"="&$B3,Results_30d_Deltas!$A$2:$H$5000,5,FALSE),"") | G3: =IFERROR(VLOOKUP($A3,Results_30d_Deltas!$A$2:$H$5000,7,FALSE)-E3,"") | H3: =IFERROR(VLOOKUP($A3,Results_30d_Deltas!$A$2:$H$5000,6,FALSE),"") | K3: =IF(B3=C3,"YES","NO") | IJ3: ez_manage.py:6076 top() | IK3: v12_quick_engine.py:4288 x7
A4: WT_15M_BOUNCE_OPEN_ENABLED | B4: True | C4: WT_15M_BOUNCE_OPEN_ENABLED=True + WT_15M_BOUNCE_BB_MAX=0.8 + BB_WT_TF=15m + GR=18 + BB_RECOVERY_FILTER_TF=OFF + DC_BREAK_FILTER_TF=1h | E4: =IF(F4="",E3,IF(F4>0,E3+F4,E3)) | F4: -0.57559161 | G4: -2.2317455 | H4: =IFERROR(VLOOKUP($A4,Results_30d_Deltas!$A$2:$H$5000,6,FALSE),"") | K4: =IF(B4=C4,"YES","NO") | IJ4: ez_manage.py:6076 top() | IK4: v12_quick_engine.py:4288 x7
A5: BB_SQUEEZE_ENTRY_ENABLED | B5: True | C5: BB_SQUEEZE_ENTRY_ENABLED=True + ADX_RANGING_THRESHOLD=25 + BB_WT_TF=15m + GR=18 + BB_RECOVERY_FILTER_TF=OFF + DC_BREAK_FILTER_TF=1h | E5: =IF(F5="",E4,IF(F5>0,E4+F5,E4)) | F5: 0 | G5: -1.6561539 | H5: =IFERROR(VLOOKUP($A5,Results_30d_Deltas!$A$2:$H$5000,6,FALSE),"") | K5: =IF(B5=C5,"YES","NO") | IJ5: ez_manage.py:4371 top() | IK5: v12_quick_engine.py:889 x9
A6: BB_PULLBACK_GATE_TF | B6: OFF | C6: BB_PULLBACK_GATE_TF=OFF + MTS_BOTTOM_STRONG_THRESHOLD=20 + BB_WT_TF=15m + GR=18 + BB_RECOVERY_FILTER_TF=OFF + DC_BREAK_FILTER_TF=1h | E6: =IF(F6="",E5,IF(F6>0,E5+F6,E5)) | F6: -2.4538266 | G6: -4.1099804 | H6: =IFERROR(VLOOKUP($A6,Results_30d_Deltas!$A$2:$H$5000,6,FALSE),"") | K6: =IF(B6=C6,"YES","NO") | IJ6: ez_manage.py:4361 top() | IK6: v12_quick_engine.py:288 x12
A7: BB_PULLBACK_GATE_TF | B7: D | E7: =IF(F7="",E6,IF(F7>0,E6+F7,E6)) | F7: 0 | G7: -1.6561539 | H7: =IFERROR(VLOOKUP($A7,Results_30d_Deltas!$A$2:$H$5000,6,FALSE),"") | K7: =IF(B7=C7,"YES","NO") | IJ7: ez_manage.py:4361 top() | IK7: v12_quick_engine.py:288 x12
A8: BB_PULLBACK_GATE_TF | B8: 4h | E8: =IF(F8="",E7,IF(F8>0,E7+F8,E7)) | F8: 0 | G8: -1.6561539 | H8: =IFERROR(VLOOKUP($A8,Results_30d_Deltas!$A$2:$H$5000,6,FALSE),"") | K8: =IF(B8=C8,"YES","NO") | IJ8: ez_manage.py:4361 top() | IK8: v12_quick_engine.py:288 x12
A9: BB_PULLBACK_GATE_TF | B9: 1h | C9: BB_PULLBACK_GATE_TF=1h + MI_TF_AGREE_MIN=0.0_ALT + BB_WT_TF=15m + GR=18 + BB_RECOVERY_FILTER_TF=OFF + DC_BREAK_FILTER_TF=1h | E9: =IF(F9="",E8,IF(F9>0,E8+F9,E8)) | F9: -1.8526111 | G9: -3.508765 | H9: =IFERROR(VLOOKUP($A9,Results_30d_Deltas!$A$2:$H$5000,6,FALSE),"") | K9: =IF(B9=C9,"YES","NO") | IJ9: ez_manage.py:4361 top() | IK9: v12_quick_engine.py:288 x12
A10: BB_PULLBACK_GATE_TF | B10: 15m | E10: =IF(F10="",E9,IF(F10>0,E9+F10,E9)) | F10: =IFERROR(VLOOKUP($A10&"="&$B10,Results_30d_Deltas!$A$2:$H$5000,5,FALSE),"") | G10: =IFERROR(VLOOKUP($A10,Results_30d_Deltas!$A$2:$H$5000,7,FALSE)-E9,"") | H10: =IFERROR(VLOOKUP($A10,Results_30d_Deltas!$A$2:$H$5000,6,FALSE),"") | K10: =IF(B10=C10,"YES","NO") | IJ10: ez_manage.py:4361 top() | IK10: v12_quick_engine.py:288 x12
A11: DELTA_GATE_BB_SQUEEZE | B11: True | E11: =IF(F11="",E10,IF(F11>0,E10+F11,E10)) | F11: =IFERROR(VLOOKUP($A11&"="&$B11,Results_30d_Deltas!$A$2:$H$5000,5,FALSE),"") | G11: =IFERROR(VLOOKUP($A11,Results_30d_Deltas!$A$2:$H$5000,7,FALSE)-E10,"") | H11: =IFERROR(VLOOKUP($A11,Results_30d_Deltas!$A$2:$H$5000,6,FALSE),"") | K11: =IF(B11=C11,"YES","NO") | IJ11: ez_manage.py:4603 top() | IK11: v12_quick_engine.py:969 x9
A12: BB_SQUEEZE_WIDTH_PERCENTILE | B12: 0.1 | E12: =IF(F12="",E11,IF(F12>0,E11+F12,E11)) | F12: -1.8526111 | G12: -3.508765 | H12: =IFERROR(VLOOKUP($A12,Results_30d_Deltas!$A$2:$H$5000,6,FALSE),"") | K12: =IF(B12=C12,"YES","NO") | IJ12: ez_manage.py:4375 top() | IK12: v12_quick_engine.py:1285 x7
A13: BB_SQUEEZE_WIDTH_PERCENTILE | B13: 0.15 | E13: =IF(F13="",E12,IF(F13>0,E12+F13,E12)) | F13: 0 | G13: -1.6561539 | H13: =IFERROR(VLOOKUP($A13,Results_30d_Deltas!$A$2:$H$5000,6,FALSE),"") | K13: =IF(B13=C13,"YES","NO") | IJ13: ez_manage.py:4375 top() | IK13: v12_quick_engine.py:1285 x7
A14: BB_SQUEEZE_WIDTH_PERCENTILE | B14: 0.2 | E14: =IF(F14="",E13,IF(F14>0,E13+F14,E13)) | F14: 0 | G14: -1.6561539 | H14: =IFERROR(VLOOKUP($A14,Results_30d_Deltas!$A$2:$H$5000,6,FALSE),"") | K14: =IF(B14=C14,"YES","NO") | IJ14: ez_manage.py:4375 top() | IK14: v12_quick_engine.py:1285 x7
A15: BB_SQUEEZE_WIDTH_PERCENTILE | B15: 0.25 | E15: =IF(F15="",E14,IF(F15>0,E14+F15,E14)) | F15: -1.8542583 | G15: -3.5104122 | H15: =IFERROR(VLOOKUP($A15,Results_30d_Deltas!$A$2:$H$5000,6,FALSE),"") | K15: =IF(B15=C15,"YES","NO") | IJ15: ez_manage.py:4375 top() | IK15: v12_quick_engine.py:1285 x7
A16: BB_SQUEEZE_WIDTH_PERCENTILE | B16: 0.3 | E16: =IF(F16="",E15,IF(F16>0,E15+F16,E15)) | F16: -1.8526111 | G16: -3.508765 | H16: =IFERROR(VLOOKUP($A16,Results_30d_Deltas!$A$2:$H$5000,6,FALSE),"") | K16: =IF(B16=C16,"YES","NO") | IJ16: ez_manage.py:4375 top() | IK16: v12_quick_engine.py:1285 x7
A17: WT_DIV_EXIT_ENABLED | B17: False | E17: =IF(F17="",E16,IF(F17>0,E16+F17,E16)) | F17: -2.0610562 | G17: -3.7172101 | H17: =IFERROR(VLOOKUP($A17,Results_30d_Deltas!$A$2:$H$5000,6,FALSE),"") | K17: =IF(B17=C17,"YES","NO") | IJ17: ez_manage.py:6086 top() | IK17: v12_quick_engine.py:4292 x3
A18: WT_DIV_EXIT_ENABLED | B18: True | E18: =IF(F18="",E17,IF(F18>0,E17+F18,E17)) | F18: =IFERROR(VLOOKUP($A18&"="&$B18,Results_30d_Deltas!$A$2:$H$5000,5,FALSE),"") | G18: =IFERROR(VLOOKUP($A18,Results_30d_Deltas!$A$2:$H$5000,7,FALSE)-E17,"") | H18: =IFERROR(VLOOKUP($A18,Results_30d_Deltas!$A$2:$H$5000,6,FALSE),"") | K18: =IF(B18=C18,"YES","NO") | IJ18: ez_manage.py:6086 top() | IK18: v12_quick_engine.py:4292 x3
A19: WT_MOMENTUM_EXIT_THRESHOLD | B19: 0 | E19: =IF(F19="",E18,IF(F19>0,E18+F19,E18)) | F19: -1.8934256 | G19: -3.5495795 | H19: =IFERROR(VLOOKUP($A19,Results_30d_Deltas!$A$2:$H$5000,6,FALSE),"") | K19: =IF(B19=C19,"YES","NO") | IJ19: ez_manage.py:6087 top() | IK19: v12_quick_engine.py:4293 x3
A20: WT_MOMENTUM_EXIT_THRESHOLD | B20: 1 | E20: =IF(F20="",E19,IF(F20>0,E19+F20,E19)) | F20: 0 | G20: -1.6561539 | H20: =IFERROR(VLOOKUP($A20,Results_30d_Deltas!$A$2:$H$5000,6,FALSE),"") | K20: =IF(B20=C20,"YES","NO") | IJ20: ez_manage.py:6087 top() | IK20: v12_quick_engine.py:4293 x3
A21: WT_MOMENTUM_EXIT_THRESHOLD | B21: 2 | E21: =IF(F21="",E20,IF(F21>0,E20+F21,E20)) | F21: -1.8526111 | G21: -3.508765 | H21: =IFERROR(VLOOKUP($A21,Results_30d_Deltas!$A$2:$H$5000,6,FALSE),"") | K21: =IF(B21=C21,"YES","NO") | IJ21: ez_manage.py:6087 top() | IK21: v12_quick_engine.py:4293 x3
A22: WT_ACCEL_EXIT_ENABLED | B22: False | E22: =IF(F22="",E21,IF(F22>0,E21+F22,E21)) | F22: 0 | G22: -1.6561539 | H22: =IFERROR(VLOOKUP($A22,Results_30d_Deltas!$A$2:$H$5000,6,FALSE),"") | K22: =IF(B22=C22,"YES","NO") | IJ22: ez_manage.py:6083 top() | IK22: v12_quick_engine.py:4290 x3
A23: WT_ACCEL_EXIT_ENABLED | B23: True | E23: =IF(F23="",E22,IF(F23>0,E22+F23,E22)) | F23: =IFERROR(VLOOKUP($A23&"="&$B23,Results_30d_Deltas!$A$2:$H$5000,5,FALSE),"") | G23: =IFERROR(VLOOKUP($A23,Results_30d_Deltas!$A$2:$H$5000,7,FALSE)-E22,"") | H23: =IFERROR(VLOOKUP($A23,Results_30d_Deltas!$A$2:$H$5000,6,FALSE),"") | K23: =IF(B23=C23,"YES","NO") | IJ23: ez_manage.py:6083 top() | IK23: v12_quick_engine.py:4290 x3

Sheet ENTRY_BREAKOUT_CHANNEL
A1: 02 ENTRY_BREAKOUT_CHANNEL - 54 bases -> 210 rows - 231 per-row FULLY CONNECTED
A2: Switch | B2: default | C2: override | D2: Family | E2: BASELINE | F2: VECTOR_DELTA | G2: LIVE_DELTA | H2: LIVE_SHARPE | I2: REAL_COMPLETE | J2: PER_ROW_FILTERS | K2: is_default (backup if bold lost) | L2: ATR_TRAIL_FILTER_TF=OFF | M2: ATR_TRAIL_FILTER_TF=D | N2: ATR_TRAIL_FILTER_TF=4h | O2: ATR_TRAIL_FILTER_TF=1h | P2: ATR_TRAIL_FILTER_TF=15m | Q2: BAR_PATTERNS_FILTER_TF=OFF | R2: BAR_PATTERNS_FILTER_TF=D | S2: BAR_PATTERNS_FILTER_TF=4h | T2: BAR_PATTERNS_FILTER_TF=1h | U2: BAR_PATTERNS_FILTER_TF=15m | V2: BB_PULLBACK_GATE_FILTER_TF=OFF | W2: BB_PULLBACK_GATE_FILTER_TF=D | X2: BB_PULLBACK_GATE_FILTER_TF=4h | Y2: BB_PULLBACK_GATE_FILTER_TF=1h | Z2: BB_PULLBACK_GATE_FILTER_TF=15m | AA2: BB_RECOVERY_ENTRY_FILTER_TF=OFF | AB2: BB_RECOVERY_ENTRY_FILTER_TF=D | AC2: BB_RECOVERY_ENTRY_FILTER_TF=4h | AD2: BB_RECOVERY_ENTRY_FILTER_TF=1h | AE2: BB_RECOVERY_ENTRY_FILTER_TF=15m | AF2: BB_RECOVERY_FILTER_TF=OFF | AG2: BB_RECOVERY_FILTER_TF=D | AH2: BB_RECOVERY_FILTER_TF=4h | AI2: BB_RECOVERY_FILTER_TF=1h | AJ2: BB_RECOVERY_FILTER_TF=15m | AK2: BREAKEVEN_GAIN_EROSION_FILTER_TF=OFF | AL2: BREAKEVEN_GAIN_EROSION_FILTER_TF=D | AM2: BREAKEVEN_GAIN_EROSION_FILTER_TF=4h | AN2: BREAKEVEN_GAIN_EROSION_FILTER_TF=1h | AO2: BREAKEVEN_GAIN_EROSION_FILTER_TF=15m | AP2: BREAKOUT_RETEST_FILTER_TF=OFF | AQ2: BREAKOUT_RETEST_FILTER_TF=D | AR2: BREAKOUT_RETEST_FILTER_TF=4h | AS2: BREAKOUT_RETEST_FILTER_TF=1h | AT2: BREAKOUT_RETEST_FILTER_TF=15m | AU2: BT_WT_CROSS_LADDER_FILTER_TF=OFF | AV2: BT_WT_CROSS_LADDER_FILTER_TF=D | AW2: BT_WT_CROSS_LADDER_FILTER_TF=4h | AX2: BT_WT_CROSS_LADDER_FILTER_TF=1h | AY2: BT_WT_CROSS_LADDER_FILTER_TF=15m | AZ2: CANDLE_PATTERN_STOPS_FILTER_TF=OFF | BA2: CANDLE_PATTERN_STOPS_FILTER_TF=D | BB2: CANDLE_PATTERN_STOPS_FILTER_TF=4h | BC2: CANDLE_PATTERN_STOPS_FILTER_TF=1h | BD2: CANDLE_PATTERN_STOPS_FILTER_TF=15m | BE2: CIRCUIT_SHARPE_GATES_FILTER_TF=OFF | BF2: CIRCUIT_SHARPE_GATES_FILTER_TF=D | BG2: CIRCUIT_SHARPE_GATES_FILTER_TF=4h | BH2: CIRCUIT_SHARPE_GATES_FILTER_TF=1h | BI2: CIRCUIT_SHARPE_GATES_FILTER_TF=15m | BJ2: DC_BREACH_REDUCE_FILTER_TF=OFF | BK2: DC_BREACH_REDUCE_FILTER_TF=D | BL2: DC_BREACH_REDUCE_FILTER_TF=4h | BM2: DC_BREACH_REDUCE_FILTER_TF=1h | BN2: DC_BREACH_REDUCE_FILTER_TF=15m | BO2: DC_BREAK_FILTER_TF=OFF | BP2: DC_BREAK_FILTER_TF=D | BQ2: DC_BREAK_FILTER_TF=4h | BR2: DC_BREAK_FILTER_TF=1h | BS2: DC_BREAK_FILTER_TF=15m | BT2: DC_MOMENTUM_BOTA_SCORER_FILTER_TF=OFF | BU2: DC_MOMENTUM_BOTA_SCORER_FILTER_TF=D | BV2: DC_MOMENTUM_BOTA_SCORER_FILTER_TF=4h | BW2: DC_MOMENTUM_BOTA_SCORER_FILTER_TF=1h | BX2: DC_MOMENTUM_BOTA_SCORER_FILTER_TF=15m | BY2: DELTA_ENGINE_FILTER_TF=OFF | BZ2: DELTA_ENGINE_FILTER_TF=D | CA2: DELTA_ENGINE_FILTER_TF=4h | CB2: DELTA_ENGINE_FILTER_TF=1h | CC2: DELTA_ENGINE_FILTER_TF=15m | CD2: EMA_9_21_FILTER_FILTER_TF=OFF | CE2: EMA_9_21_FILTER_FILTER_TF=D | CF2: EMA_9_21_FILTER_FILTER_TF=4h | CG2: EMA_9_21_FILTER_FILTER_TF=1h | CH2: EMA_9_21_FILTER_FILTER_TF=15m | CI2: EMA_BLANKET_FILTER_FILTER_TF=OFF | CJ2: EMA_BLANKET_FILTER_FILTER_TF=D | CK2: EMA_BLANKET_FILTER_FILTER_TF=4h | CL2: EMA_BLANKET_FILTER_FILTER_TF=1h | CM2: EMA_BLANKET_FILTER_FILTER_TF=15m | CN2: EMERGENCY_BRAKE_FILTER_TF=OFF | CO2: EMERGENCY_BRAKE_FILTER_TF=D | CP2: EMERGENCY_BRAKE_FILTER_TF=4h | CQ2: EMERGENCY_BRAKE_FILTER_TF=1h | CR2: EMERGENCY_BRAKE_FILTER_TF=15m | CS2: EXIT_R1_R2_FILTER_TF=OFF | CT2: EXIT_R1_R2_FILTER_TF=D | CU2: EXIT_R1_R2_FILTER_TF=4h | CV2: EXIT_R1_R2_FILTER_TF=1h | CW2: EXIT_R1_R2_FILTER_TF=15m | CX2: EXIT_TIGHT_BREAKOUT_SCORER_FILTER_TF=OFF | CY2: EXIT_TIGHT_BREAKOUT_SCORER_FILTER_TF=D | CZ2: EXIT_TIGHT_BREAKOUT_SCORER_FILTER_TF=4h | DA2: EXIT_TIGHT_BREAKOUT_SCORER_FILTER_TF=1h | DB2: EXIT_TIGHT_BREAKOUT_SCORER_FILTER_TF=15m | DC2: EXIT_TOP_FADE_FILTER_TF=OFF | DD2: EXIT_TOP_FADE_FILTER_TF=D | DE2: EXIT_TOP_FADE_FILTER_TF=4h | DF2: EXIT_TOP_FADE_FILTER_TF=1h | DG2: EXIT_TOP_FADE_FILTER_TF=15m | DH2: EXIT_TO_REDUCE_ADAPTER_FILTER_TF=OFF | DI2: EXIT_TO_REDUCE_ADAPTER_FILTER_TF=D | DJ2: EXIT_TO_REDUCE_ADAPTER_FILTER_TF=4h | DK2: EXIT_TO_REDUCE_ADAPTER_FILTER_TF=1h | DL2: EXIT_TO_REDUCE_ADAPTER_FILTER_TF=15m | DM2: FAST_RISER_FILTER_TF=OFF | DN2: FAST_RISER_FILTER_TF=D | DO2: FAST_RISER_FILTER_TF=4h | DP2: FAST_RISER_FILTER_TF=1h | DQ2: FAST_RISER_FILTER_TF=15m | DR2: FH_MOMENTUM_FILTER_TF=OFF | DS2: FH_MOMENTUM_FILTER_TF=D | DT2: FH_MOMENTUM_FILTER_TF=4h | DU2: FH_MOMENTUM_FILTER_TF=1h | DV2: FH_MOMENTUM_FILTER_TF=15m | DW2: FIRST_OPEN_THROTTLE_FILTER_TF=OFF | DX2: FIRST_OPEN_THROTTLE_FILTER_TF=D | DY2: FIRST_OPEN_THROTTLE_FILTER_TF=4h | DZ2: FIRST_OPEN_THROTTLE_FILTER_TF=1h | EA2: FIRST_OPEN_THROTTLE_FILTER_TF=15m | EB2: FROZEN_STOP_FILTER_TF=OFF | EC2: FROZEN_STOP_FILTER_TF=D | ED2: FROZEN_STOP_FILTER_TF=4h | EE2: FROZEN_STOP_FILTER_TF=1h | EF2: FROZEN_STOP_FILTER_TF=15m | EG2: GOLDEN_RULE_ENFORCE_FILTER_TF=OFF | EH2: GOLDEN_RULE_ENFORCE_FILTER_TF=D | EI2: GOLDEN_RULE_ENFORCE_FILTER_TF=4h | EJ2: GOLDEN_RULE_ENFORCE_FILTER_TF=1h | EK2: GOLDEN_RULE_ENFORCE_FILTER_TF=15m | EL2: GOLDEN_RULE_HTF_VOTE_FILTER_TF=OFF | EM2: GOLDEN_RULE_HTF_VOTE_FILTER_TF=D | EN2: GOLDEN_RULE_HTF_VOTE_FILTER_TF=4h | EO2: GOLDEN_RULE_HTF_VOTE_FILTER_TF=1h | EP2: GOLDEN_RULE_HTF_VOTE_FILTER_TF=15m | EQ2: GR_FILTER_VEC_FILTER_TF=OFF | ER2: GR_FILTER_VEC_FILTER_TF=D | ES2: GR_FILTER_VEC_FILTER_TF=4h | ET2: GR_FILTER_VEC_FILTER_TF=1h | EU2: GR_FILTER_VEC_FILTER_TF=15m | EV2: GR_V5_STATE_FILTER_TF=OFF | EW2: GR_V5_STATE_FILTER_TF=D | EX2: GR_V5_STATE_FILTER_TF=4h | EY2: GR_V5_STATE_FILTER_TF=1h | EZ2: GR_V5_STATE_FILTER_TF=15m | FA2: HAIKU_WINNER_FILTER_TF=OFF | FB2: HAIKU_WINNER_FILTER_TF=D | FC2: HAIKU_WINNER_FILTER_TF=4h | FD2: HAIKU_WINNER_FILTER_TF=1h | FE2: HAIKU_WINNER_FILTER_TF=15m | FF2: LH_HL_FILTER_TF_REQ=2 | FG2: LH_HL_FILTER_TF_REQ=2_ALT | FH2: LIVE_ENTRY_ENGINE_FILTER_TF=OFF | FI2: LIVE_ENTRY_ENGINE_FILTER_TF=D | FJ2: LIVE_ENTRY_ENGINE_FILTER_TF=4h | FK2: LIVE_ENTRY_ENGINE_FILTER_TF=1h | FL2: LIVE_ENTRY_ENGINE_FILTER_TF=15m | FM2: LIVE_ONLY_SIGNALS_BATCH5_FILTER_TF=OFF | FN2: LIVE_ONLY_SIGNALS_BATCH5_FILTER_TF=D | FO2: LIVE_ONLY_SIGNALS_BATCH5_FILTER_TF=4h | FP2: LIVE_ONLY_SIGNALS_BATCH5_FILTER_TF=1h | FQ2: LIVE_ONLY_SIGNALS_BATCH5_FILTER_TF=15m | FR2: MANDATORY_REENTRY_WT_FILTER_TF_MODE=15m_only | FS2: MANDATORY_REENTRY_WT_FILTER_TF_MODE=15m_only_ALT | FT2: MOM3_FILTER_TF=OFF | FU2: MOM3_FILTER_TF=D | FV2: MOM3_FILTER_TF=4h | FW2: MOM3_FILTER_TF=1h | FX2: MOM3_FILTER_TF=15m | FY2: MOMENTUM_BREAKOUT_FILTER_TF=OFF | FZ2: MOMENTUM_BREAKOUT_FILTER_TF=D | GA2: MOMENTUM_BREAKOUT_FILTER_TF=4h | GB2: MOMENTUM_BREAKOUT_FILTER_TF=1h | GC2: MOMENTUM_BREAKOUT_FILTER_TF=15m | GD2: MTF_ARMED_ENTRIES_FILTER_TF=OFF | GE2: MTF_ARMED_ENTRIES_FILTER_TF=D | GF2: MTF_ARMED_ENTRIES_FILTER_TF=4h | GG2: MTF_ARMED_ENTRIES_FILTER_TF=1h | GH2: MTF_ARMED_ENTRIES_FILTER_TF=15m | GI2: MTF_ATR_TRAIL_FILTER_TF=OFF | GJ2: MTF_ATR_TRAIL_FILTER_TF=D | GK2: MTF_ATR_TRAIL_FILTER_TF=4h | GL2: MTF_ATR_TRAIL_FILTER_TF=1h | GM2: MTF_ATR_TRAIL_FILTER_TF=15m | GN2: MTF_DC_REJECT_FILTER_TF=OFF | GO2: MTF_DC_REJECT_FILTER_TF=D | GP2: MTF_DC_REJECT_FILTER_TF=4h | GQ2: MTF_DC_REJECT_FILTER_TF=1h | GR2: MTF_DC_REJECT_FILTER_TF=15m | GS2: NEWBORN_LOSS_KILL_FILTER_TF=OFF | GT2: NEWBORN_LOSS_KILL_FILTER_TF=D | GU2: NEWBORN_LOSS_KILL_FILTER_TF=4h | GV2: NEWBORN_LOSS_KILL_FILTER_TF=1h | GW2: NEWBORN_LOSS_KILL_FILTER_TF=15m | GX2: NEWBORN_PROTECT_FILTER_TF=OFF | GY2: NEWBORN_PROTECT_FILTER_TF=D | GZ2: NEWBORN_PROTECT_FILTER_TF=4h | HA2: NEWBORN_PROTECT_FILTER_TF=1h | HB2: NEWBORN_PROTECT_FILTER_TF=15m | HC2: NOLOSS_BYPASS_WT5OF5_FILTER_TF=OFF | HD2: NOLOSS_BYPASS_WT5OF5_FILTER_TF=D | HE2: NOLOSS_BYPASS_WT5OF5_FILTER_TF=4h | HF2: NOLOSS_BYPASS_WT5OF5_FILTER_TF=1h | HG2: NOLOSS_BYPASS_WT5OF5_FILTER_TF=15m | HH2: OPEN_INTENT_SIZE_GATES_FILTER_TF=OFF | HI2: OPEN_INTENT_SIZE_GATES_FILTER_TF=D | HJ2: OPEN_INTENT_SIZE_GATES_FILTER_TF=4h | HK2: OPEN_INTENT_SIZE_GATES_FILTER_TF=1h | HL2: OPEN_INTENT_SIZE_GATES_FILTER_TF=15m | HM2: PARTIAL_PROFIT_LOCK_V2_FILTER_TF=OFF | HN2: PARTIAL_PROFIT_LOCK_V2_FILTER_TF=D | HO2: PARTIAL_PROFIT_LOCK_V2_FILTER_TF=4h | HP2: PARTIAL_PROFIT_LOCK_V2_FILTER_TF=1h | HQ2: PARTIAL_PROFIT_LOCK_V2_FILTER_TF=15m | HR2: PEAK_GIVEBACK_BE_EROSION_FILTER_TF=OFF | HS2: PEAK_GIVEBACK_BE_EROSION_FILTER_TF=D | HT2: PEAK_GIVEBACK_BE_EROSION_FILTER_TF=4h | HU2: PEAK_GIVEBACK_BE_EROSION_FILTER_TF=1h | HV2: PEAK_GIVEBACK_BE_EROSION_FILTER_TF=15m | HW2: WT_15M_BOUNCE_BB_MAX=0.95 | HX2: WT_15M_BOUNCE_BB_MAX=0.9 | HY2: WT_15M_BOUNCE_BB_MAX=0.8 | HZ2: WT_15M_BOUNCE_BB_MIN=0.05 | IA2: WT_15M_BOUNCE_BB_MIN=0.1 | IB2: WT_15M_BOUNCE_BB_MIN=0.2 | IC2: WT_15M_BOUNCE_HIGH_1H_GT_PREV=True | ID2: WT_15M_BOUNCE_HIGH_1H_GT_PREV=False | IE2: WT_15M_BOUNCE_LOW_1H_GT_PREV=True | IF2: WT_15M_BOUNCE_LOW_1H_GT_PREV=False | IG2: WT_15M_BOUNCE_REL_VOL_GT_1=True | IH2: WT_15M_BOUNCE_REL_VOL_GT_1=False | II2: Live Location | IJ2: Vec Hook | IK2: Type | IL2: Correct Options
A3: DC_BREAKOUT_TF | B3: OFF | E3: =MAX('ENTRY_REVERSAL_BOUNCE'!E:E) | F3: -1.0393426 | G3: -2.6954965 | H3: =IFERROR(VLOOKUP($A3,Results_30d_Deltas!$A$2:$H$5000,6,FALSE),"") | K3: =IF(B3=C3,"YES","NO") | IJ3: ez_manage.py:3078 top() | IK3: v12_quick_engine.py:1518 x5
A4: DC_BREAKOUT_TF | B4: D | E4: =IF(F4="",E3,IF(F4>0,E3+F4,E3)) | F4: 0 | G4: -1.6561539 | H4: =IFERROR(VLOOKUP($A4,Results_30d_Deltas!$A$2:$H$5000,6,FALSE),"") | K4: =IF(B4=C4,"YES","NO") | IJ4: ez_manage.py:3078 top() | IK4: v12_quick_engine.py:1518 x5
A5: DC_BREAKOUT_TF | B5: 4h | E5: =IF(F5="",E4,IF(F5>0,E4+F5,E4)) | F5: 0 | G5: -1.6561539 | H5: =IFERROR(VLOOKUP($A5,Results_30d_Deltas!$A$2:$H$5000,6,FALSE),"") | K5: =IF(B5=C5,"YES","NO") | IJ5: ez_manage.py:3078 top() | IK5: v12_quick_engine.py:1518 x5
A6: DC_BREAKOUT_TF | B6: 1h | E6: =IF(F6="",E5,IF(F6>0,E5+F6,E5)) | F6: -2.0245238 | G6: -3.6806777 | H6: =IFERROR(VLOOKUP($A6,Results_30d_Deltas!$A$2:$H$5000,6,FALSE),"") | K6: =IF(B6=C6,"YES","NO") | IJ6: ez_manage.py:3078 top() | IK6: v12_quick_engine.py:1518 x5
A7: DC_BREAKOUT_TF | B7: 15m | E7: =IF(F7="",E6,IF(F7>0,E6+F7,E6)) | F7: =IFERROR(VLOOKUP($A7&"="&$B7,Results_30d_Deltas!$A$2:$H$5000,5,FALSE),"") | G7: =IFERROR(VLOOKUP($A7,Results_30d_Deltas!$A$2:$H$5000,7,FALSE)-E6,"") | H7: =IFERROR(VLOOKUP($A7,Results_30d_Deltas!$A$2:$H$5000,6,FALSE),"") | K7: =IF(B7=C7,"YES","NO") | IJ7: ez_manage.py:3078 top() | IK7: v12_quick_engine.py:1518 x5
A8: DC_BREAKOUT_SCORE | B8: 10 | E8: =IF(F8="",E7,IF(F8>0,E7+F8,E7)) | F8: -1.8526111 | G8: -3.508765 | H8: =IFERROR(VLOOKUP($A8,Results_30d_Deltas!$A$2:$H$5000,6,FALSE),"") | K8: =IF(B8=C8,"YES","NO") | IJ8: ez_manage.py:3077 top() | IK8: v12_quick_engine.py:1517 x18
A9: DC_BREAKOUT_SCORE | B9: 15 | E9: =IF(F9="",E8,IF(F9>0,E8+F9,E8)) | F9: 0 | G9: -1.6561539 | H9: =IFERROR(VLOOKUP($A9,Results_30d_Deltas!$A$2:$H$5000,6,FALSE),"") | K9: =IF(B9=C9,"YES","NO") | IJ9: ez_manage.py:3077 top() | IK9: v12_quick_engine.py:1517 x18
A10: DC_BREAKOUT_SCORE | B10: 20 | E10: =IF(F10="",E9,IF(F10>0,E9+F10,E9)) | F10: 0 | G10: -1.6561539 | H10: =IFERROR(VLOOKUP($A10,Results_30d_Deltas!$A$2:$H$5000,6,FALSE),"") | K10: =IF(B10=C10,"YES","NO") | IJ10: ez_manage.py:3077 top() | IK10: v12_quick_engine.py:1517 x18
A11: DC_BREAKOUT_SCORE | B11: 25 | E11: =IF(F11="",E10,IF(F11>0,E10+F11,E10)) | F11: -2.0245238 | G11: -3.6806777 | H11: =IFERROR(VLOOKUP($A11,Results_30d_Deltas!$A$2:$H$5000,6,FALSE),"") | K11: =IF(B11=C11,"YES","NO") | IJ11: ez_manage.py:3077 top() | IK11: v12_quick_engine.py:1517 x18
A12: DC_BREAKOUT_SCORE | B12: 30 | E12: =IF(F12="",E11,IF(F12>0,E11+F12,E11)) | F12: -2.0245238 | G12: -3.6806777 | H12: =IFERROR(VLOOKUP($A12,Results_30d_Deltas!$A$2:$H$5000,6,FALSE),"") | K12: =IF(B12=C12,"YES","NO") | IJ12: ez_manage.py:3077 top() | IK12: v12_quick_engine.py:1517 x18
A13: BB_BREAKOUT_SCORE | B13: 10 | E13: =IF(F13="",E12,IF(F13>0,E12+F13,E12)) | F13: 0 | G13: -1.6561539 | H13: =IFERROR(VLOOKUP($A13,Results_30d_Deltas!$A$2:$H$5000,6,FALSE),"") | K13: =IF(B13=C13,"YES","NO") | IJ13: ez_manage.py:2963 top() | IK13: v12_quick_engine.py:1255 x6
A14: BB_BREAKOUT_SCORE | B14: 15 | E14: =IF(F14="",E13,IF(F14>0,E13+F14,E13)) | F14: -2.0610562 | G14: -3.7172101 | H14: =IFERROR(VLOOKUP($A14,Results_30d_Deltas!$A$2:$H$5000,6,FALSE),"") | K14: =IF(B14=C14,"YES","NO") | IJ14: ez_manage.py:2963 top() | IK14: v12_quick_engine.py:1255 x6
A15: BB_BREAKOUT_SCORE | B15: 20 | E15: =IF(F15="",E14,IF(F15>0,E14+F15,E14)) | F15: -2.0610562 | G15: -3.7172101 | H15: =IFERROR(VLOOKUP($A15,Results_30d_Deltas!$A$2:$H$5000,6,FALSE),"") | K15: =IF(B15=C15,"YES","NO") | IJ15: ez_manage.py:2963 top() | IK15: v12_quick_engine.py:1255 x6
A16: BB_BREAKOUT_SCORE | B16: 25 | E16: =IF(F16="",E15,IF(F16>0,E15+F16,E15)) | F16: 0 | G16: -1.6561539 | H16: =IFERROR(VLOOKUP($A16,Results_30d_Deltas!$A$2:$H$5000,6,FALSE),"") | K16: =IF(B16=C16,"YES","NO") | IJ16: ez_manage.py:2963 top() | IK16: v12_quick_engine.py:1255 x6
A17: BB_BREAKOUT_SCORE | B17: 30 | E17: =IF(F17="",E16,IF(F17>0,E16+F17,E16)) | F17: 0 | G17: -1.6561539 | H17: =IFERROR(VLOOKUP($A17,Results_30d_Deltas!$A$2:$H$5000,6,FALSE),"") | K17: =IF(B17=C17,"YES","NO") | IJ17: ez_manage.py:2963 top() | IK17: v12_quick_engine.py:1255 x6
A18: STDEV_BREAKOUT_ENABLED | B18: False | E18: =IF(F18="",E17,IF(F18>0,E17+F18,E17)) | F18: =IFERROR(VLOOKUP($A18&"="&$B18,Results_30d_Deltas!$A$2:$H$5000,5,FALSE),"") | G18: =IFERROR(VLOOKUP($A18,Results_30d_Deltas!$A$2:$H$5000,7,FALSE)-E17,"") | H18: =IFERROR(VLOOKUP($A18,Results_30d_Deltas!$A$2:$H$5000,6,FALSE),"") | K18: =IF(B18=C18,"YES","NO") | IJ18: ez_manage.py:4039 top() | IK18: v12_quick_engine.py:3275 x6
A19: STDEV_BREAKOUT_ENABLED | B19: True | E19: =IF(F19="",E18,IF(F19>0,E18+F19,E18)) | F19: 0 | G19: -1.6561539 | H19: =IFERROR(VLOOKUP($A19,Results_30d_Deltas!$A$2:$H$5000,6,FALSE),"") | K19: =IF(B19=C19,"YES","NO") | IJ19: ez_manage.py:4039 top() | IK19: v12_quick_engine.py:3275 x6
A20: BTC_BREAKOUT_ENTRY_ENABLED | B20: False | E20: =IF(F20="",E19,IF(F20>0,E19+F20,E19)) | F20: =IFERROR(VLOOKUP($A20&"="&$B20,Results_30d_Deltas!$A$2:$H$5000,5,FALSE),"") | G20: =IFERROR(VLOOKUP($A20,Results_30d_Deltas!$A$2:$H$5000,7,FALSE)-E19,"") | H20: =IFERROR(VLOOKUP($A20,Results_30d_Deltas!$A$2:$H$5000,6,FALSE),"") | K20: =IF(B20=C20,"YES","NO") | IJ20: ez_manage.py:4432 top() | IK20: v12_quick_engine.py:393 x8
A21: BTC_BREAKOUT_ENTRY_ENABLED | B21: True | E21: =IF(F21="",E20,IF(F21>0,E20+F21,E20)) | F21: 0 | G21: -1.6561539 | H21: =IFERROR(VLOOKUP($A21,Results_30d_Deltas!$A$2:$H$5000,6,FALSE),"") | K21: =IF(B21=C21,"YES","NO") | IJ21: ez_manage.py:4432 top() | IK21: v12_quick_engine.py:393 x8
A22: RZ_BREAKOUT_ENTRY_ENABLED | B22: False | E22: =IF(F22="",E21,IF(F22>0,E21+F22,E21)) | F22: =IFERROR(VLOOKUP($A22&"="&$B22,Results_30d_Deltas!$A$2:$H$5000,5,FALSE),"") | G22: =IFERROR(VLOOKUP($A22,Results_30d_Deltas!$A$2:$H$5000,7,FALSE)-E21,"") | H22: =IFERROR(VLOOKUP($A22,Results_30d_Deltas!$A$2:$H$5000,6,FALSE),"") | K22: =IF(B22=C22,"YES","NO") | IJ22: ez_manage.py:5398 top() | IK22: v12_quick_engine.py:3021 x3
A23: RZ_BREAKOUT_ENTRY_ENABLED | B23: True | E23: =IF(F23="",E22,IF(F23>0,E22+F23,E22)) | F23: -2.0245238 | G23: -3.6806777 | H23: =IFERROR(VLOOKUP($A23,Results_30d_Deltas!$A$2:$H$5000,6,FALSE),"") | K23: =IF(B23=C23,"YES","NO") | IJ23: ez_manage.py:5398 top() | IK23: v12_quick_engine.py:3021 x3
A24: ATR_ADAPTIVE_SIZING_TARGET_PCT | B24: 1.0 | E24: =IF(F24="",E23,IF(F24>0,E23+F24,E23)) | F24: 0 | G24: -1.6561539 | H24: =IFERROR(VLOOKUP($A24,Results_30d_Deltas!$A$2:$H$5000,6,FALSE),"") | K24: =IF(B24=C24,"YES","NO") | IJ24: ez_manage.py:4327 top() | IK24: v12_quick_engine.py:1209 x7
A25: ATR_ADAPTIVE_SIZING_TARGET_PCT | B25: 1.5 | E25: =IF(F25="",E24,IF(F25>0,E24+F25,E24)) | F25: -1.7073607 | G25: -3.3635146 | H25: =IFERROR(VLOOKUP($A25,Results_30d_Deltas!$A$2:$H$5000,6,FALSE),"") | K25: =IF(B25=C25,"YES","NO") | IJ25: ez_manage.py:4327 top() | IK25: v12_quick_engine.py:1209 x7
A26: ATR_ADAPTIVE_SIZING_TARGET_PCT | B26: 2.0 | E26: =IF(F26="",E25,IF(F26>0,E25+F26,E25)) | F26: -2.0245238 | G26: -3.6806777 | H26: =IFERROR(VLOOKUP($A26,Results_30d_Deltas!$A$2:$H$5000,6,FALSE),"") | K26: =IF(B26=C26,"YES","NO") | IJ26: ez_manage.py:4327 top() | IK26: v12_quick_engine.py:1209 x7
A27: ATR_ADAPTIVE_SIZING_TARGET_PCT | B27: 2.5 | E27: =IF(F27="",E26,IF(F27>0,E26+F27,E26)) | F27: 0 | G27: -1.6561539 | H27: =IFERROR(VLOOKUP($A27,Results_30d_Deltas!$A$2:$H$5000,6,FALSE),"") | K27: =IF(B27=C27,"YES","NO") | IJ27: ez_manage.py:4327 top() | IK27: v12_quick_engine.py:1209 x7
A28: ATR_ADAPTIVE_SIZING_TARGET_PCT | B28: 3.0 | E28: =IF(F28="",E27,IF(F28>0,E27+F28,E27)) | F28: 0 | G28: -1.6561539 | H28: =IFERROR(VLOOKUP($A28,Results_30d_Deltas!$A$2:$H$5000,6,FALSE),"") | K28: =IF(B28=C28,"YES","NO") | IJ28: ez_manage.py:4327 top() | IK28: v12_quick_engine.py:1209 x7
A29: ATR_ADAPTIVE_STOP_MULT | B29: 1.0 | E29: =IF(F29="",E28,IF(F29>0,E28+F29,E28)) | F29: -2.4538266 | G29: -4.1099804 | H29: =IFERROR(VLOOKUP($A29,Results_30d_Deltas!$A$2:$H$5000,6,FALSE),"") | K29: =IF(B29=C29,"YES","NO") | IJ29: ez_manage.py:4329 top() | IK29: v12_quick_engine.py:1211 x6
A30: ATR_ADAPTIVE_STOP_MULT | B30: 1.5 | E30: =IF(F30="",E29,IF(F30>0,E29+F30,E29)) | F30: 0 | G30: -1.6561539 | H30: =IFERROR(VLOOKUP($A30,Results_30d_Deltas!$A$2:$H$5000,6,FALSE),"") | K30: =IF(B30=C30,"YES","NO") | IJ30: ez_manage.py:4329 top() | IK30: v12_quick_engine.py:1211 x6
A31: ATR_ADAPTIVE_STOP_MULT | B31: 2.0 | E31: =IF(F31="",E30,IF(F31>0,E30+F31,E30)) | F31: 0 | G31: -1.6561539 | H31: =IFERROR(VLOOKUP($A31,Results_30d_Deltas!$A$2:$H$5000,6,FALSE),"") | K31: =IF(B31=C31,"YES","NO") | IJ31: ez_manage.py:4329 top() | IK31: v12_quick_engine.py:1211 x6
A32: ATR_ADAPTIVE_STOP_MULT | B32: 2.5 | E32: =IF(F32="",E31,IF(F32>0,E31+F32,E31)) | F32: -2.4538266 | G32: -4.1099804 | H32: =IFERROR(VLOOKUP($A32,Results_30d_Deltas!$A$2:$H$5000,6,FALSE),"") | K32: =IF(B32=C32,"YES","NO") | IJ32: ez_manage.py:4329 top() | IK32: v12_quick_engine.py:1211 x6
A33: ATR_ADAPTIVE_STOP_MULT | B33: 3.0 | E33: =IF(F33="",E32,IF(F33>0,E32+F33,E32)) | F33: -1.8542583 | G33: -3.5104122 | H33: =IFERROR(VLOOKUP($A33,Results_30d_Deltas!$A$2:$H$5000,6,FALSE),"") | K33: =IF(B33=C33,"YES","NO") | IJ33: ez_manage.py:4329 top() | IK33: v12_quick_engine.py:1211 x6
A34: ATR_LONG_WINDOW | B34: 50 | E34: =IF(F34="",E33,IF(F34>0,E33+F34,E33)) | F34: 0 | G34: -1.6561539 | H34: =IFERROR(VLOOKUP($A34,Results_30d_Deltas!$A$2:$H$5000,6,FALSE),"") | K34: =IF(B34=C34,"YES","NO") | IJ34: ez_manage.py:4330 top() | IK34: v12_quick_engine.py:199 x5
... A48: ENTRY_PRIMARY_TF | B48: D | E48: =IF(F48="",E47,IF(F48>0,E47+F48,E47)) | F48: 0 | G48: -1.6561539 | H48: =IFERROR(VLOOKUP($A48,Results_30d_Deltas!$A$2:$H$5000,6,FALSE),"") | K48: =IF(B48=C48,"YES","NO") | IJ48: ez_manage.py:3216 top() | IK48: v12_quick_engine.py:1728 x4
A49: ENTRY_PRIMARY_TF | B49: 4h | E49: =IF(F49="",E48,IF(F49>0,E48+F49,E48)) | F49: =IFERROR(VLOOKUP($A49&"="&$B49,Results_30d_Deltas!$A$2:$H$5000,5,FALSE),"") | G49: =IFERROR(VLOOKUP($A49,Results_30d_Deltas!$A$2:$H$5000,7,FALSE)-E48,"") | H49: =IFERROR(VLOOKUP($A49,Results_30d_Deltas!$A$2:$H$5000,6,FALSE),"") | K49: =IF(B49=C49,"YES","NO") | IJ49: ez_manage.py:3216 top() | IK49: v12_quick_engine.py:1728 x4
A50: ENTRY_PRIMARY_TF | B50: 1h | E50: =IF(F50="",E49,IF(F50>0,E49+F50,E49)) | F50: -1.0393426 | G50: -2.6954965 | H50: =IFERROR(VLOOKUP($A50,Results_30d_Deltas!$A$2:$H$5000,6,FALSE),"") | K50: =IF(B50=C50,"YES","NO") | IJ50: ez_manage.py:3216 top() | IK50: v12_quick_engine.py:1728 x4
A51: ENTRY_PRIMARY_TF | B51: 15m | E51: =IF(F51="",E50,IF(F51>0,E50+F51,E50)) | F51: -1.0393426 | G51: -2.6954965 | H51: =IFERROR(VLOOKUP($A51,Results_30d_Deltas!$A$2:$H$5000,6,FALSE),"") | K51: =IF(B51=C51,"YES","NO") | IJ51: ez_manage.py:3216 top() | IK51: v12_quick_engine.py:1728 x4
A52: ENTRY_SCORE_THRESHOLD | B52: 9.0 | E52: =IF(F52="",E51,IF(F52>0,E51+F52,E51)) | F52: 0 | G52: -1.6561539 | H52: =IFERROR(VLOOKUP($A52,Results_30d_Deltas!$A$2:$H$5000,6,FALSE),"") | K52: =IF(B52=C52,"YES","NO") | IJ52: ez_manage.py:4644 top() | IK52: v12_quick_engine.py:3394 x9
A53: ENTRY_SCORE_THRESHOLD | B53: 13.5 | E53: =IF(F53="",E52,IF(F53>0,E52+F53,E52)) | F53: 0 | G53: -1.6561539 | H53: =IFERROR(VLOOKUP($A53,Results_30d_Deltas!$A$2:$H$5000,6,FALSE),"") | K53: =IF(B53=C53,"YES","NO") | IJ53: ez_manage.py:4644 top() | IK53: v12_quick_engine.py:3394 x9
...

Sheet ENTRY_CONFIRMATION_GATES
A1: 03 ENTRY_CONFIRMATION_GATES - 4 bases -> 11 rows - 231 per-row FULLY CONNECTED
A2: Switch | B2: default | C2: override | D2: Family | E2: BASELINE | F2: VECTOR_DELTA | G2: LIVE_DELTA | H2: LIVE_SHARPE | I2: REAL_COMPLETE | J2: PER_ROW_FILTERS | K2: is_default (backup if bold lost) | L2: ATR_TRAIL_FILTER_TF=OFF | M2: ATR_TRAIL_FILTER_TF=D | N2: ATR_TRAIL_FILTER_TF=4h | O2: ATR_TRAIL_FILTER_TF=1h | P2: ATR_TRAIL_FILTER_TF=15m | Q2: BAR_PATTERNS_FILTER_TF=OFF | R2: BAR_PATTERNS_FILTER_TF=D | S2: BAR_PATTERNS_FILTER_TF=4h | T2: BAR_PATTERNS_FILTER_TF=1h | U2: BAR_PATTERNS_FILTER_TF=15m | V2: BB_PULLBACK_GATE_FILTER_TF=OFF | W2: BB_PULLBACK_GATE_FILTER_TF=D | X2: BB_PULLBACK_GATE_FILTER_TF=4h | Y2: BB_PULLBACK_GATE_FILTER_TF=1h | Z2: BB_PULLBACK_GATE_FILTER_TF=15m | AA2: BB_RECOVERY_ENTRY_FILTER_TF=OFF | AB2: BB_RECOVERY_ENTRY_FILTER_TF=D | AC2: BB_RECOVERY_ENTRY_FILTER_TF=4h | AD2: BB_RECOVERY_ENTRY_FILTER_TF=1h | AE2: BB_RECOVERY_ENTRY_FILTER_TF=15m | AF2: BB_RECOVERY_FILTER_TF=OFF | AG2: BB_RECOVERY_FILTER_TF=D | AH2: BB_RECOVERY_FILTER_TF=4h | AI2: BB_RECOVERY_FILTER_TF=1h | AJ2: BB_RECOVERY_FILTER_TF=15m | AK2: BREAKEVEN_GAIN_EROSION_FILTER_TF=OFF | AL2: BREAKEVEN_GAIN_EROSION_FILTER_TF=D | AM2: BREAKEVEN_GAIN_EROSION_FILTER_TF=4h | AN2: BREAKEVEN_GAIN_EROSION_FILTER_TF=1h | AO2: BREAKEVEN_GAIN_EROSION_FILTER_TF=15m | AP2: BREAKOUT_RETEST_FILTER_TF=OFF | AQ2: BREAKOUT_RETEST_FILTER_TF=D | AR2: BREAKOUT_RETEST_FILTER_TF=4h | AS2: BREAKOUT_RETEST_FILTER_TF=1h | AT2: BREAKOUT_RETEST_FILTER_TF=15m | AU2: BT_WT_CROSS_LADDER_FILTER_TF=OFF | AV2: BT_WT_CROSS_LADDER_FILTER_TF=D | AW2: BT_WT_CROSS_LADDER_FILTER_TF=4h | AX2: BT_WT_CROSS_LADDER_FILTER_TF=1h | AY2: BT_WT_CROSS_LADDER_FILTER_TF=15m | AZ2: CANDLE_PATTERN_STOPS_FILTER_TF=OFF | BA2: CANDLE_PATTERN_STOPS_FILTER_TF=D | BB2: CANDLE_PATTERN_STOPS_FILTER_TF=4h | BC2: CANDLE_PATTERN_STOPS_FILTER_TF=1h | BD2: CANDLE_PATTERN_STOPS_FILTER_TF=15m | BE2: CIRCUIT_SHARPE_GATES_FILTER_TF=OFF | BF2: CIRCUIT_SHARPE_GATES_FILTER_TF=D | BG2: CIRCUIT_SHARPE_GATES_FILTER_TF=4h | BH2: CIRCUIT_SHARPE_GATES_FILTER_TF=1h | BI2: CIRCUIT_SHARPE_GATES_FILTER_TF=15m | BJ2: DC_BREACH_REDUCE_FILTER_TF=OFF | BK2: DC_BREACH_REDUCE_FILTER_TF=D | BL2: DC_BREACH_REDUCE_FILTER_TF=4h | BM2: DC_BREACH_REDUCE_FILTER_TF=1h | BN2: DC_BREACH_REDUCE_FILTER_TF=15m | BO2: DC_BREAK_FILTER_TF=OFF | BP2: DC_BREAK_FILTER_TF=D | BQ2: DC_BREAK_FILTER_TF=4h | BR2: DC_BREAK_FILTER_TF=1h | BS2: DC_BREAK_FILTER_TF=15m | BT2: DC_MOMENTUM_BOTA_SCORER_FILTER_TF=OFF | BU2: DC_MOMENTUM_BOTA_SCORER_FILTER_TF=D | BV2: DC_MOMENTUM_BOTA_SCORER_FILTER_TF=4h | BW2: DC_MOMENTUM_BOTA_SCORER_FILTER_TF=1h | BX2: DC_MOMENTUM_BOTA_SCORER_FILTER_TF=15m | BY2: DELTA_ENGINE_FILTER_TF=OFF | BZ2: DELTA_ENGINE_FILTER_TF=D | CA2: DELTA_ENGINE_FILTER_TF=4h | CB2: DELTA_ENGINE_FILTER_TF=1h | CC2: DELTA_ENGINE_FILTER_TF=15m | CD2: EMA_9_21_FILTER_FILTER_TF=OFF | CE2: EMA_9_21_FILTER_FILTER_TF=D | CF2: EMA_9_21_FILTER_FILTER_TF=4h | CG2: EMA_9_21_FILTER_FILTER_TF=1h | CH2: EMA_9_21_FILTER_FILTER_TF=15m | CI2: EMA_BLANKET_FILTER_FILTER_TF=OFF | CJ2: EMA_BLANKET_FILTER_FILTER_TF=D | CK2: EMA_BLANKET_FILTER_FILTER_TF=4h | CL2: EMA_BLANKET_FILTER_FILTER_TF=1h | CM2: EMA_BLANKET_FILTER_FILTER_TF=15m | CN2: EMERGENCY_BRAKE_FILTER_TF=OFF | CO2: EMERGENCY_BRAKE_FILTER_TF=D | CP2: EMERGENCY_BRAKE_FILTER_TF=4h | CQ2: EMERGENCY_BRAKE_FILTER_TF=1h | CR2: EMERGENCY_BRAKE_FILTER_TF=15m | CS2: EXIT_R1_R2_FILTER_TF=OFF | CT2: EXIT_R1_R2_FILTER_TF=D | CU2: EXIT_R1_R2_FILTER_TF=4h | CV2: EXIT_R1_R2_FILTER_TF=1h | CW2: EXIT_R1_R2_FILTER_TF=15m | CX2: EXIT_TIGHT_BREAKOUT_SCORER_FILTER_TF=OFF | CY2: EXIT_TIGHT_BREAKOUT_SCORER_FILTER_TF=D | CZ2: EXIT_TIGHT_BREAKOUT_SCORER_FILTER_TF=4h | DA2: EXIT_TIGHT_BREAKOUT_SCORER_FILTER_TF=1h | DB2: EXIT_TIGHT_BREAKOUT_SCORER_FILTER_TF=15m | DC2: EXIT_TOP_FADE_FILTER_TF=OFF | DD2: EXIT_TOP_FADE_FILTER_TF=D | DE2: EXIT_TOP_FADE_FILTER_TF=4h | DF2: EXIT_TOP_FADE_FILTER_TF=1h | DG2: EXIT_TOP_FADE_FILTER_TF=15m | DH2: EXIT_TO_REDUCE_ADAPTER_FILTER_TF=OFF | DI2: EXIT_TO_REDUCE_ADAPTER_FILTER_TF=D | DJ2: EXIT_TO_REDUCE_ADAPTER_FILTER_TF=4h | DK2: EXIT_TO_REDUCE_ADAPTER_FILTER_TF=1h | DL2: EXIT_TO_REDUCE_ADAPTER_FILTER_TF=15m | DM2: FAST_RISER_FILTER_TF=OFF | DN2: FAST_RISER_FILTER_TF=D | DO2: FAST_RISER_FILTER_TF=4h | DP2: FAST_RISER_FILTER_TF=1h | DQ2: FAST_RISER_FILTER_TF=15m | DR2: FH_MOMENTUM_FILTER_TF=OFF | DS2: FH_MOMENTUM_FILTER_TF=D | DT2: FH_MOMENTUM_FILTER_TF=4h | DU2: FH_MOMENTUM_FILTER_TF=1h | DV2: FH_MOMENTUM_FILTER_TF=15m | DW2: FIRST_OPEN_THROTTLE_FILTER_TF=OFF | DX2: FIRST_OPEN_THROTTLE_FILTER_TF=D | DY2: FIRST_OPEN_THROTTLE_FILTER_TF=4h | DZ2: FIRST_OPEN_THROTTLE_FILTER_TF=1h | EA2: FIRST_OPEN_THROTTLE_FILTER_TF=15m | EB2: FROZEN_STOP_FILTER_TF=OFF | EC2: FROZEN_STOP_FILTER_TF=D | ED2: FROZEN_STOP_FILTER_TF=4h | EE2: FROZEN_STOP_FILTER_TF=1h | EF2: FROZEN_STOP_FILTER_TF=15m | EG2: GOLDEN_RULE_ENFORCE_FILTER_TF=OFF | EH2: GOLDEN_RULE_ENFORCE_FILTER_TF=D | EI2: GOLDEN_RULE_ENFORCE_FILTER_TF=4h | EJ2: GOLDEN_RULE_ENFORCE_FILTER_TF=1h | EK2: GOLDEN_RULE_ENFORCE_FILTER_TF=15m | EL2: GOLDEN_RULE_HTF_VOTE_FILTER_TF=OFF | EM2: GOLDEN_RULE_HTF_VOTE_FILTER_TF=D | EN2: GOLDEN_RULE_HTF_VOTE_FILTER_TF=4h | EO2: GOLDEN_RULE_HTF_VOTE_FILTER_TF=1h | EP2: GOLDEN_RULE_HTF_VOTE_FILTER_TF=15m | EQ2: GR_FILTER_VEC_FILTER_TF=OFF | ER2: GR_FILTER_VEC_FILTER_TF=D | ES2: GR_FILTER_VEC_FILTER_TF=4h | ET2: GR_FILTER_VEC_FILTER_TF=1h | EU2: GR_FILTER_VEC_FILTER_TF=15m | EV2: GR_V5_STATE_FILTER_TF=OFF | EW2: GR_V5_STATE_FILTER_TF=D | EX2: GR_V5_STATE_FILTER_TF=4h | EY2: GR_V5_STATE_FILTER_TF=1h | EZ2: GR_V5_STATE_FILTER_TF=15m | FA2: HAIKU_WINNER_FILTER_TF=OFF | FB2: HAIKU_WINNER_FILTER_TF=D | FC2: HAIKU_WINNER_FILTER_TF=4h | FD2: HAIKU_WINNER_FILTER_TF=1h | FE2: HAIKU_WINNER_FILTER_TF=15m | FF2: LH_HL_FILTER_TF_REQ=2 | FG2: LH_HL_FILTER_TF_REQ=2_ALT | FH2: LIVE_ENTRY_ENGINE_FILTER_TF=OFF | FI2: LIVE_ENTRY_ENGINE_FILTER_TF=D | FJ2: LIVE_ENTRY_ENGINE_FILTER_TF=4h | FK2: LIVE_ENTRY_ENGINE_FILTER_TF=1h | FL2: LIVE_ENTRY_ENGINE_FILTER_TF=15m | FM2: LIVE_ONLY_SIGNALS_BATCH5_FILTER_TF=OFF | FN2: LIVE_ONLY_SIGNALS_BATCH5_FILTER_TF=D | FO2: LIVE_ONLY_SIGNALS_BATCH5_FILTER_TF=4h | FP2: LIVE_ONLY_SIGNALS_BATCH5_FILTER_TF=1h | FQ2: LIVE_ONLY_SIGNALS_BATCH5_FILTER_TF=15m | FR2: MANDATORY_REENTRY_WT_FILTER_TF_MODE=15m_only | FS2: MANDATORY_REENTRY_WT_FILTER_TF_MODE=15m_only_ALT | FT2: MOM3_FILTER_TF=OFF | FU2: MOM3_FILTER_TF=D | FV2: MOM3_FILTER_TF=4h | FW2: MOM3_FILTER_TF=1h | FX2: MOM3_FILTER_TF=15m | FY2: MOMENTUM_BREAKOUT_FILTER_TF=OFF | FZ2: MOMENTUM_BREAKOUT_FILTER_TF=D | GA2: MOMENTUM_BREAKOUT_FILTER_TF=4h | GB2: MOMENTUM_BREAKOUT_FILTER_TF=1h | GC2: MOMENTUM_BREAKOUT_FILTER_TF=15m | GD2: MTF_ARMED_ENTRIES_FILTER_TF=OFF | GE2: MTF_ARMED_ENTRIES_FILTER_TF=D | GF2: MTF_ARMED_ENTRIES_FILTER_TF=4h | GG2: MTF_ARMED_ENTRIES_FILTER_TF=1h | GH2: MTF_ARMED_ENTRIES_FILTER_TF=15m | GI2: MTF_ATR_TRAIL_FILTER_TF=OFF | GJ2: MTF_ATR_TRAIL_FILTER_TF=D | GK2: MTF_ATR_TRAIL_FILTER_TF=4h | GL2: MTF_ATR_TRAIL_FILTER_TF=1h | GM2: MTF_ATR_TRAIL_FILTER_TF=15m | GN2: MTF_DC_REJECT_FILTER_TF=OFF | GO2: MTF_DC_REJECT_FILTER_TF=D | GP2: MTF_DC_REJECT_FILTER_TF=4h | GQ2: MTF_DC_REJECT_FILTER_TF=1h | GR2: MTF_DC_REJECT_FILTER_TF=15m | GS2: NEWBORN_LOSS_KILL_FILTER_TF=OFF | GT2: NEWBORN_LOSS_KILL_FILTER_TF=D | GU2: NEWBORN_LOSS_KILL_FILTER_TF=4h | GV2: NEWBORN_LOSS_KILL_FILTER_TF=1h | GW2: NEWBORN_LOSS_KILL_FILTER_TF=15m | GX2: NEWBORN_PROTECT_FILTER_TF=OFF | GY2: NEWBORN_PROTECT_FILTER_TF=D | GZ2: NEWBORN_PROTECT_FILTER_TF=4h | HA2: NEWBORN_PROTECT_FILTER_TF=1h | HB2: NEWBORN_PROTECT_FILTER_TF=15m | HC2: NOLOSS_BYPASS_WT5OF5_FILTER_TF=OFF | HD2: NOLOSS_BYPASS_WT5OF5_FILTER_TF=D | HE2: NOLOSS_BYPASS_WT5OF5_FILTER_TF=4h | HF2: NOLOSS_BYPASS_WT5OF5_FILTER_TF=1h | HG2: NOLOSS_BYPASS_WT5OF5_FILTER_TF=15m | HH2: OPEN_INTENT_SIZE_GATES_FILTER_TF=OFF | HI2: OPEN_INTENT_SIZE_GATES_FILTER_TF=D | HJ2: OPEN_INTENT_SIZE_GATES_FILTER_TF=4h | HK2: OPEN_INTENT_SIZE_GATES_FILTER_TF=1h | HL2: OPEN_INTENT_SIZE_GATES_FILTER_TF=15m | HM2: PARTIAL_PROFIT_LOCK_V2_FILTER_TF=OFF | HN2: PARTIAL_PROFIT_LOCK_V2_FILTER_TF=D | HO2: PARTIAL_PROFIT_LOCK_V2_FILTER_TF=4h | HP2: PARTIAL_PROFIT_LOCK_V2_FILTER_TF=1h | HQ2: PARTIAL_PROFIT_LOCK_V2_FILTER_TF=15m | HR2: PEAK_GIVEBACK_BE_EROSION_FILTER_TF=OFF | HS2: PEAK_GIVEBACK_BE_EROSION_FILTER_TF=D | HT2: PEAK_GIVEBACK_BE_EROSION_FILTER_TF=4h | HU2: PEAK_GIVEBACK_BE_EROSION_FILTER_TF=1h | HV2: PEAK_GIVEBACK_BE_EROSION_FILTER_TF=15m | HW2: WT_15M_BOUNCE_BB_MAX=0.95 | HX2: WT_15M_BOUNCE_BB_MAX=0.9 | HY2: WT_15M_BOUNCE_BB_MAX=0.8 | HZ2: WT_15M_BOUNCE_BB_MIN=0.05 | IA2: WT_15M_BOUNCE_BB_MIN=0.1 | IB2: WT_15M_BOUNCE_BB_MIN=0.2 | IC2: WT_15M_BOUNCE_HIGH_1H_GT_PREV=True | ID2: WT_15M_BOUNCE_HIGH_1H_GT_PREV=False | IE2: WT_15M_BOUNCE_LOW_1H_GT_PREV=True | IF2: WT_15M_BOUNCE_LOW_1H_GT_PREV=False | IG2: WT_15M_BOUNCE_REL_VOL_GT_1=True | IH2: WT_15M_BOUNCE_REL_VOL_GT_1=False | II2: Live Location | IJ2: Vec Hook | IK2: Type | IL2: Correct Options
A3: GR_FILTER_ALL_ENTRIES | B3: 0.0 | E3: =MAX('ENTRY_BREAKOUT_CHANNEL'!E:E) | F3: -1.8934256 | G3: -3.5495795 | H3: =IFERROR(VLOOKUP($A3,Results_30d_Deltas!$A$2:$H$5000,6,FALSE),"") | K3: =IF(B3=C3,"YES","NO") | IJ3: ez_manage.py:4768 top() | IK3: v12_quick_engine.py:1912 x3
A4: GR_FILTER_ALL_ENTRIES | B4: 0.0_ALT | C4: GR_FILTER_ALL_ENTRIES=0.0_ALT + EXIT_TO_REDUCE_ADAPTER_FILTER_TF=4h + BB_WT_TF=15m + GR=18 + BB_RECOVERY_FILTER_TF=OFF + DC_BREAK_FILTER_TF=1h | E4: =IF(F4="",E3,IF(F4>0,E3+F4,E3)) | F4: -1.8934256 | G4: -3.5495795 | H4: =IFERROR(VLOOKUP($A4,Results_30d_Deltas!$A$2:$H$5000,6,FALSE),"") | K4: =IF(B4=C4,"YES","NO") | IJ4: ez_manage.py:4768 top() | IK4: v12_quick_engine.py:1912 x3
A5: GR_FILTER_VEC_ENABLED | B5: False | E5: =IF(F5="",E4,IF(F5>0,E4+F5,E4)) | F5: =IFERROR(VLOOKUP($A5&"="&$B5,Results_30d_Deltas!$A$2:$H$5000,5,FALSE),"") | G5: =IFERROR(VLOOKUP($A5,Results_30d_Deltas!$A$2:$H$5000,7,FALSE)-E4,"") | H5: =IFERROR(VLOOKUP($A5,Results_30d_Deltas!$A$2:$H$5000,6,FALSE),"") | K5: =IF(B5=C5,"YES","NO") | IJ5: ez_manage.py:6003 top() | IK5: v12_quick_engine.py:4261 x2
A6: GR_FILTER_VEC_ENABLED | B6: True | E6: =IF(F6="",E5,IF(F6>0,E5+F6,E5)) | F6: -1.8526111 | G6: -3.508765 | H6: =IFERROR(VLOOKUP($A6,Results_30d_Deltas!$A$2:$H$5000,6,FALSE),"") | K6: =IF(B6=C6,"YES","NO") | IJ6: ez_manage.py:6003 top() | IK6: v12_quick_engine.py:4261 x2
A7: GR_FILTER_VEC_FILTER_TF | B7: OFF | E7: =IF(F7="",E6,IF(F7>0,E6+F7,E6)) | F7: -2.0610562 | G7: -3.7172101 | H7: =IFERROR(VLOOKUP($A7,Results_30d_Deltas!$A$2:$H$5000,6,FALSE),"") | K7: =IF(B7=C7,"YES","NO") | IJ7: ez_manage.py:6004 top() | IK7: v12_quick_engine.py:112 x3
A8: GR_FILTER_VEC_FILTER_TF | B8: D | E8: =IF(F8="",E7,IF(F8>0,E7+F8,E7)) | F8: -1.8136634 | G8: -3.4698173 | H8: =IFERROR(VLOOKUP($A8,Results_30d_Deltas!$A$2:$H$5000,6,FALSE),"") | K8: =IF(B8=C8,"YES","NO") | IJ8: ez_manage.py:6004 top() | IK8: v12_quick_engine.py:112 x3
A9: GR_FILTER_VEC_FILTER_TF | B9: 4h | E9: =IF(F9="",E8,IF(F9>0,E8+F9,E8)) | F9: -1.8526111 | G9: -3.508765 | H9: =IFERROR(VLOOKUP($A9,Results_30d_Deltas!$A$2:$H$5000,6,FALSE),"") | K9: =IF(B9=C9,"YES","NO") | IJ9: ez_manage.py:6004 top() | IK9: v12_quick_engine.py:112 x3
A10: GR_FILTER_VEC_FILTER_TF | B10: 1h | E10: =IF(F10="",E9,IF(F10>0,E9+F10,E9)) | F10: -2.0245238 | G10: -3.6806777 | H10: =IFERROR(VLOOKUP($A10,Results_30d_Deltas!$A$2:$H$5000,6,FALSE),"") | K10: =IF(B10=C10,"YES","NO") | IJ10: ez_manage.py:6004 top() | IK10: v12_quick_engine.py:112 x3
A11: GR_FILTER_VEC_FILTER_TF | B11: 15m | E11: =IF(F11="",E10,IF(F11>0,E10+F11,E10)) | F11: =IFERROR(VLOOKUP($A11&"="&$B11,Results_30d_Deltas!$A$2:$H$5000,5,FALSE),"") | G11: =IFERROR(VLOOKUP($A11,Results_30d_Deltas!$A$2:$H$5000,7,FALSE)-E10,"") | H11: =IFERROR(VLOOKUP($A11,Results_30d_Deltas!$A$2:$H$5000,6,FALSE),"") | K11: =IF(B11=C11,"YES","NO") | IJ11: ez_manage.py:6004 top() | IK11: v12_quick_engine.py:112 x3
A12: WT_AGAINST_FILTER_ENABLED | B12: False | E12: =IF(F12="",E11,IF(F12>0,E11+F12,E11)) | F12: =IFERROR(VLOOKUP($A12&"="&$B12,Results_30d_Deltas!$A$2:$H$5000,5,FALSE),"") | G12: =IFERROR(VLOOKUP($A12,Results_30d_Deltas!$A$2:$H$5000,7,FALSE)-E11,"") | H12: =IFERROR(VLOOKUP($A12,Results_30d_Deltas!$A$2:$H$5000,6,FALSE),"") | K12: =IF(B12=C12,"YES","NO") | IJ12: ez_manage.py:6084 top() | IK12: v12_quick_engine.py:4291 x2
A13: WT_AGAINST_FILTER_ENABLED | B13: True | E13: =IF(F13="",E12,IF(F13>0,E12+F13,E12)) | F13: 0 | G13: -1.6561539 | H13: =IFERROR(VLOOKUP($A13,Results_30d_Deltas!$A$2:$H$5000,6,FALSE),"") | K13: =IF(B13=C13,"YES","NO") | IJ13: ez_manage.py:6084 top() | IK13: v12_quick_engine.py:4291 x2

Sheet EXIT_STRUCTURAL
A1: 04 EXIT_STRUCTURAL - 2 bases -> 6 rows - 231 per-row FULLY CONNECTED
